Workbook

Sheet 每日指數值
A1: date | B1: price_index | C1: total_return_index | D1: price_daily_return | E1: tr_daily_return
A2: 2024-01-03 | B2: 100 | C2: 100
A3: 2024-01-04 | B3: 99.968476 | C3: 100.09495 | D3: -0.00031523592 | E3: 0.00094949081
A4: 2024-01-05 | B4: 99.615001 | C4: 99.741026 | D4: -0.0035358711 | E4: -0.0035358711
A5: 2024-01-08 | B5: 100.04105 | C5: 100.16762 | D5: 0.004276984 | E5: 0.004276984
A6: 2024-01-09 | B6: 99.944013 | C6: 100.07045 | D6: -0.00096999827 | E6: -0.00096999827
A7: 2024-01-10 | B7: 99.585939 | C7: 99.711927 | D7: -0.0035827468 | E7: -0.0035827468
A8: 2024-01-11 | B8: 100.00249 | C8: 100.129 | D8: 0.004182796 | E8: 0.004182796
A9: 2024-01-12 | B9: 99.934967 | C9: 100.0614 | D9: -0.00067517291 | E9: -0.00067517291
A10: 2024-01-15 | B10: 99.959929 | C10: 100.08639 | D10: 0.00024978174 | E10: 0.00024978174
A11: 2024-01-16 | B11: 98.648522 | C11: 98.773325 | D11: -0.01311933 | E11: -0.01311933
A12: 2024-01-17 | B12: 97.508968 | C12: 97.632329 | D12: -0.011551656 | E12: -0.011551656
A13: 2024-01-18 | B13: 98.045718 | C13: 98.169758 | D13: 0.0055046137 | E13: 0.0055046137
A14: 2024-01-19 | B14: 101.06611 | C14: 101.20521 | D14: 0.030805976 | E14: 0.030920483
... A479: 2025-12-22 | B479: 162.74254 | C479: 174.52565 | D479: 0.014328456 | E479: 0.014328456

Sheet 投資後權重
A1: date | B1: 1101 | C1: 1216 | D1: 1301 | E1: 1303 | F1: 1326 | G1: 1590 | H1: 2002 | I1: 2059 | J1: 2207 | K1: 2301 | L1: 2303 | M1: 2308 | N1: 2317 | O1: 2327 | P1: 2330 | Q1: 2345 | R1: 2357 | S1: 2360 | T1: 2379 | U1: 2382 | V1: 2383 | W1: 2395 | X1: 2408 | Y1: 2412 | Z1: 2454 | AA1: 2603 | AB1: 2609 | AC1: 2615 | AD1: 2618 | AE1: 2801 | AF1: 2880 | AG1: 2881 | AH1: 2882 | AI1: 2883 | AJ1: 2884 | AK1: 2885 | AL1: 2886 | AM1: 2887 | AN1: 2888 | AO1: 2890 | AP1: 2891 | AQ1: 2892 | AR1: 2912 | AS1: 3008 | AT1: 3017 | AU1: 3034 | AV1: 3037 | AW1: 3045 | AX1: 3231 | AY1: 3293 | AZ1: 3443 | BA1: 3529 | BB1: 3653 | BC1: 3661 | BD1: 3711 | BE1: 4904 | BF1: 4938 | BG1: 5871 | BH1: 5876 | BI1: 5880 | BJ1: 6488 | BK1: 6505 | BL1: 6669 | BM1: 6919 | BN1: 8069
A2: 2024-01-03 | B2: 0.0085195677 | C2: 0.013330686 | D2: 0.015977926 | E2: 0.016720322 | F2: 0.011509403 | H2: 0.013534765 | J2: 0.012264334 | K2: 0.0085076765 | L2: 0.020376065 | M2: 0.025419544 | N2: 0.046558253 | O2: 0.007859445 | P2: 0.3 | Q2: 0.0088252038 | R2: 0.011100602 | T2: 0.0074506446 | U2: 0.026565599 | W2: 0.0099233729 | X2: 0.0072787042 | Y2: 0.029917312 | Z2: 0.048995308 | AA2: 0.010596994 | AF2: 0.0096460185 | AG2: 0.029920205 | AH2: 0.023406395 | AI2: 0.0072803111 | AJ2: 0.012887497 | AK2: 0.010990368 | AL2: 0.017888553 | AM2: 0.0077887405 | AO2: 0.0076765775 | AP2: 0.018237576 | AQ2: 0.011818574 | AR2: 0.0089206549 | AS2: 0.011520008 | AU2: 0.0097684658 | AV2: 0.0083325222 | AW2: 0.011834001 | AX2: 0.0087136836 | AZ2: 0.0070627342 | BC2: 0.0082261441 | BD2: 0.017807886 | BE2: 0.0092009017 | BF2: 0.0073548722 | BG2: 0.010888489 | BH2: 0.0071871097 | BI2: 0.012456521 | BJ2: 0.0080310641 | BK2: 0.024400114 | BL2: 0.0095222857 | BO2: =24.6/每日收盤價!Z2 -> 0.025813221
A3: 2024-01-04 | B3: =B2*(1+$BO$2)*(1+每日報酬率!B3) -> 0.0087394852 | C3: =C2*(1+$BO$2)*(1+每日報酬率!C3) -> 0.013581131 | D3: =D2*(1+$BO$2)*(1+每日報酬率!D3) -> 0.01643234 | E3: =E2*(1+$BO$2)*(1+每日報酬率!E3) -> 0.017151928 | F3: =F2*(1+$BO$2)*(1+每日報酬率!F3) -> 0.011806498 | G3: =G2*(1+$BO$2)*(1+每日報酬率!G3) -> 0 | H3: =H2*(1+$BO$2)*(1+每日報酬率!H3) -> 0.01388414 | I3: =I2*(1+$BO$2)*(1+每日報酬率!I3) -> 0 | ... Y3: =Y2*(1+$BO$2)*(1+每日報酬率!Y3) -> 0.030433828 | Z3: =Z2*(1+每日報酬率!Z3) -> 0.047710016 | AA3: =AA2*(1+$BO$2)*(1+每日報酬率!AA3) -> 0.011291331 | AB3: =AB2*(1+$BO$2)*(1+每日報酬率!AB3) -> 0 | AC3: =AC2*(1+$BO$2)*(1+每日報酬率!AC3) -> 0 | AD3: =AD2*(1+$BO$2)*(1+每日報酬率!AD3) -> 0 | AE3: =AE2*(1+$BO$2)*(1+每日報酬率!AE3) -> 0 | AF3: =AF2*(1+$BO$2)*(1+每日報酬率!AF3) -> 0.0098950133 | AG3: =AG2*(1+$BO$2)*(1+每日報酬率!AG3) -> 0.030596176 | AH3: =AH2*(1+$BO$2)*(1+每日報酬率!AH3) -> 0.023877049 | ... BN3: =BN2*(1+$BO$2)*(1+每日報酬率!BN3) -> 0 | BT3: =SUM(B3:BN3) -> 1.0242583
A4: 2024-01-05 | B4: =B3*(1+每日報酬率!B4) -> 0.0087778163 | C4: =C3*(1+每日報酬率!C4) -> 0.013637328 | D4: =D3*(1+每日報酬率!D4) -> 0.016390367 | E4: =E3*(1+每日報酬率!E4) -> 0.017099635 | F4: =F3*(1+每日報酬率!F4) -> 0.011787174 | G4: =G3*(1+每日報酬率!G4) -> 0 | H4: =H3*(1+每日報酬率!H4) -> 0.01388414 | I4: =I3*(1+每日報酬率!I4) -> 0 | ... BN4: =BN3*(1+每日報酬率!BN4) -> 0 | BT4: =SUM(B4:BN4) -> 1.0206364
A5: 2024-01-08 | B5: =B4*(1+每日報酬率!B5) -> 0.0087522622 | C5: =C4*(1+每日報酬率!C5) -> 0.013674794 | D5: =D4*(1+每日報酬率!D5) -> 0.016390367 | E5: =E4*(1+每日報酬率!E5) -> 0.01720422 | F5: =F4*(1+每日報酬率!F5) -> 0.011787174 | G5: =G4*(1+每日報酬率!G5) -> 0 | H5: =H4*(1+每日報酬率!H5) -> 0.013780139 | I5: =I4*(1+每日報酬率!I5) -> 0 | ... BN5: =BN4*(1+每日報酬率!BN5) -> 0 | BT5: =SUM(B5:BN5) -> 1.0250013
A6: 2024-01-09 | B6: =B5*(1+每日報酬率!B6) -> 0.0087011541 | C6: =C5*(1+每日報酬率!C6) -> 0.013581131 | D6: =D5*(1+每日報酬率!D6) -> 0.016285435 | E6: =E5*(1+每日報酬率!E6) -> 0.017021197 | F6: =F5*(1+每日報酬率!F6) -> 0.011748528 | G6: =G5*(1+每日報酬率!G6) -> 0 | H6: =H5*(1+每日報酬率!H6) -> 0.013520137 | I6: =I5*(1+每日報酬率!I6) -> 0 | ... BN6: =BN5*(1+每日報酬率!BN6) -> 0 | BT6: =SUM(B6:BN6) -> 1.0240077
A7: 2024-01-10 | B7: =B6*(1+每日報酬率!B7) -> 0.0086117149 | C7: =C6*(1+每日報酬率!C7) -> 0.013581131 | D7: =D6*(1+每日報酬率!D7) -> 0.016159517 | E7: =E6*(1+每日報酬率!E7) -> 0.016864319 | F7: =F6*(1+每日報酬率!F7) -> 0.011651912 | G7: =G6*(1+每日報酬率!G7) -> 0 | H7: =H6*(1+每日報酬率!H7) -> 0.013442136 | I7: =I6*(1+每日報酬率!I7) -> 0 | ... BN7: =BN6*(1+每日報酬率!BN7) -> 0 | BT7: =SUM(B7:BN7) -> 1.0203389
A8: 2024-01-11 | B8: =B7*(1+每日報酬率!B8) -> 0.0086117149 | C8: =C7*(1+每日報酬率!C8) -> 0.013543666 | D8: =D7*(1+每日報酬率!D8) -> 0.015928667 | E8: =E7*(1+每日報酬率!E8) -> 0.016602857 | F8: =F7*(1+每日報酬率!F8) -> 0.011651912 | G8: =G7*(1+每日報酬率!G8) -> 0 | H8: =H7*(1+每日報酬率!H8) -> 0.013416136 | I8: =I7*(1+每日報酬率!I8) -> 0 | ... BN8: =BN7*(1+每日報酬率!BN8) -> 0 | BT8: =SUM(B8:BN8) -> 1.0246062
A9: 2024-01-12 | B9: =B8*(1+每日報酬率!B9) -> 0.008624492 | C9: =C8*(1+每日報酬率!C9) -> 0.013599863 | D9: =D8*(1+每日報酬率!D9) -> 0.015949653 | E9: =E8*(1+每日報酬率!E9) -> 0.016733588 | F9: =F8*(1+每日報酬率!F9) -> 0.011613265 | G9: =G8*(1+每日報酬率!G9) -> 0 | H9: =H8*(1+每日報酬率!H9) -> 0.013416136 | I9: =I8*(1+每日報酬率!I9) -> 0 | ... BN9: =BN8*(1+每日報酬率!BN9) -> 0 | BT9: =SUM(B9:BN9) -> 1.0239149
A10: 2024-01-15 | B10: =B9*(1+每日報酬率!B10) -> 0.0085989379 | C10: =C9*(1+每日報酬率!C10) -> 0.013524933 | D10: =D9*(1+每日報酬率!D10) -> 0.015844721 | E10: =E9*(1+每日報酬率!E10) -> 0.016629003 | F10: =F9*(1+每日報酬率!F10) -> 0.011535972 | G10: =G9*(1+每日報酬率!G10) -> 0 | H10: =H9*(1+每日報酬率!H10) -> 0.013416136 | I10: =I9*(1+每日報酬率!I10) -> 0 | ... BN10: =BN9*(1+每日報酬率!BN10) -> 0 | BT10: =SUM(B10:BN10) -> 1.0241703
A11: 2024-01-16 | B11: =B10*(1+每日報酬率!B11) -> 0.0084072825 | C11: =C10*(1+每日報酬率!C11) -> 0.013337607 | D11: =D10*(1+每日報酬率!D11) -> 0.01544598 | E11: =E10*(1+每日報酬率!E11) -> 0.016158371 | F11: =F10*(1+每日報酬率!F11) -> 0.011014245 | G11: =G10*(1+每日報酬率!G11) -> 0 | H11: =H10*(1+每日報酬率!H11) -> 0.013104133 | I11: =I10*(1+每日報酬率!I11) -> 0 | ... BN11: =BN10*(1+每日報酬率!BN11) -> 0 | BT11: =SUM(B11:BN11) -> 1.0107328
A12: 2024-01-17 | B12: =B11*(1+每日報酬率!B12) -> 0.0082284042 | C12: =C11*(1+每日報酬率!C12) -> 0.013169014 | D12: =D11*(1+每日報酬率!D12) -> 0.015068225 | E12: =E11*(1+每日報酬率!E12) -> 0.015713885 | F12: =F11*(1+每日報酬率!F12) -> 0.010782366 | G12: =G11*(1+每日報酬率!G12) -> 0 | H12: =H11*(1+每日報酬率!H12) -> 0.01289613 | I12: =I11*(1+每日報酬率!I12) -> 0 | ... BN12: =BN11*(1+每日報酬率!BN12) -> 0 | BT12: =SUM(B12:BN12) -> 0.99905678
A13: 2024-01-18 | B13: =B12*(1+每日報酬率!B13) -> 0.0081900731 | C13: =C12*(1+每日報酬率!C13) -> 0.013318874 | D13: =D12*(1+每日報酬率!D13) -> 0.01492132 | E13: =E12*(1+每日報酬率!E13) -> 0.015713885 | F13: =F12*(1+每日報酬率!F13) -> 0.010782366 | G13: =G12*(1+每日報酬率!G13) -> 0 | H13: =H12*(1+每日報酬率!H13) -> 0.01289613 | I13: =I12*(1+每日報酬率!I13) -> 0 | ... BN13: =BN12*(1+每日報酬率!BN13) -> 0 | BT13: =SUM(B13:BN13) -> 1.0045571
A14: 2024-01-19 | B14: =B13*(1+每日報酬率!B14) -> 0.0082795123 | C14: =C13*(1+每日報酬率!C14) -> 0.013393805 | D14: =D13*(1+每日報酬率!D14) -> 0.014942307 | E14: =E13*(1+每日報酬率!E14) -> 0.015687739 | F14: =F13*(1+每日報酬率!F14) -> 0.010801689 | G14: =G13*(1+每日報酬率!G14) -> 0 | H14: =H13*(1+每日報酬率!H14) -> 0.01281813 | I14: =I13*(1+每日報酬率!I14) -> 0 | ... BN14: =BN13*(1+每日報酬率!BN14) -> 0 | BT14: =SUM(B14:BN14) -> 1.0355032
A15: 2024-01-22 | B15: =B14*(1+每日報酬率!B15) -> 0.0082539582 | C15: =C14*(1+每日報酬率!C15) -> 0.013225211 | D15: =D14*(1+每日報酬率!D15) -> 0.014816388 | E15: =E14*(1+每日報酬率!E15) -> 0.015557008 | F15: =F14*(1+每日報酬率!F15) -> 0.01074372 | G15: =G14*(1+每日報酬率!G15) -> 0 | H15: =H14*(1+每日報酬率!H15) -> 0.01287013 | I15: =I14*(1+每日報酬率!I15) -> 0 | ... BN15: =BN14*(1+每日報酬率!BN15) -> 0 | BT15: =SUM(B15:BN15) -> 1.0418811
... A479: 2025-12-22 | B479: =B478*(1+每日報酬率!B479) -> 0.0063885126 | C479: =C478*(1+每日報酬率!C479) -> 0.014573958 | D479: =D478*(1+每日報酬率!D479) -> 0.0084260339 | E479: =E478*(1+每日報酬率!E479) -> 0.015792324 | F479: =F478*(1+每日報酬率!F479) -> 0.0051786274 | G479: =G478*(1+每日報酬率!G479) -> 0 | H479: =H478*(1+每日報酬率!H479) -> 0.0097760989 | I479: =I478*(1+每日報酬率!I479) -> 0 | ... BN479: =BN478*(1+每日報酬率!BN479) -> 0 | BT479: =SUM(B479:BN479) -> 1.7231352

Sheet 現金股利
A1: date | B1: 1101 | C1: 1216 | D1: 1301 | E1: 1303 | F1: 1326 | G1: 1590 | H1: 2002 | I1: 2059 | J1: 2207 | K1: 2301 | L1: 2303 | M1: 2308 | N1: 2317 | O1: 2327 | P1: 2330 | Q1: 2345 | R1: 2357 | S1: 2360 | T1: 2379 | U1: 2382 | V1: 2383 | W1: 2395 | X1: 2408 | Y1: 2412 | Z1: 2454 | AA1: 2603 | AB1: 2609 | AC1: 2615 | AD1: 2618 | AE1: 2801 | AF1: 2880 | AG1: 2881 | AH1: 2882 | AI1: 2883 | AJ1: 2884 | AK1: 2885 | AL1: 2886 | AM1: 2887 | AN1: 2888 | AO1: 2890 | AP1: 2891 | AQ1: 2892 | AR1: 2912 | AS1: 3008 | AT1: 3017 | AU1: 3034 | AV1: 3037 | AW1: 3045 | AX1: 3231 | AY1: 3293 | AZ1: 3443 | BA1: 3529 | BB1: 3653 | BC1: 3661 | BD1: 3711 | BE1: 4904 | BF1: 4938 | BG1: 5871 | BH1: 5876 | BI1: 5880 | BJ1: 6488 | BK1: 6505 | BL1: 6669 | BM1: 6919 | BN1: 8096 | BP1: date | BQ1: 1101 | BR1: 1216 | BS1: 1301 | BT1: 1303 | BU1: 1326 | BV1: 1590 | BW1: 2002 | BX1: 2059 | BY1: 2207 | BZ1: 2301 | CA1: 2303 | CB1: 2308 | CC1: 2317 | CD1: 2327 | CE1: 2330 | CF1: 2345 | CG1: 2357 | CH1: 2360 | CI1: 2379 | CJ1: 2382 | CK1: 2383 | CL1: 2395 | CM1: 2408 | CN1: 2412 | CO1: 2454 | CP1: 2603 | CQ1: 2609 | CR1: 2615 | CS1: 2618 | CT1: 2801 | CU1: 2880 | CV1: 2881 | CW1: 2882 | CX1: 2883 | CY1: 2884 | CZ1: 2885 | DA1: 2886 | DB1: 2887 | DC1: 2888 | DD1: 2890 | DE1: 2891 | DF1: 2892 | DG1: 2912 | DH1: 3008 | DI1: 3017 | DJ1: 3034 | DK1: 3037 | DL1: 3045 | DM1: 3231 | DN1: 3293 | DO1: 3443 | DP1: 3529 | DQ1: 3653 | DR1: 3661 | DS1: 3711 | DT1: 4904 | DU1: 4938 | DV1: 5871 | DW1: 5876 | DX1: 5880 | DY1: 6488 | DZ1: 6505 | EA1: 6669 | EB1: 6919 | EC1: 8096
A2: 41347 | BP2: 41347
A3: 41373 | BP3: 41373
A4: 41388 | BP4: 41388
A5: 41403 | BP5: 41403
A6: 41411 | BP6: 41411
A7: 41414 | BP7: 41414
A8: 41415 | BP8: 41415
A9: 41416 | BP9: 41416
A10: 41417 | BP10: 41417
A11: 41418 | BP11: 41418
A12: 41422 | BP12: 41422
A13: 41423 | BP13: 41423
... A17: 41431 | BP17: 41431
A18: 41432 | G18: 3.8 | BP18: 41432
A19: 41435 | BP19: 41435
A20: 41436 | BP20: 41436
A21: 41438 | BP21: 41438
A22: 41442 | BP22: 41442
A23: 41443 | BP23: 41443
A24: 41444 | BP24: 41444
A25: 41445 | BP25: 41445
A26: 41446 | BP26: 41446
A27: 41449 | BP27: 41449
A28: 41450 | BP28: 41450
A29: 41451 | BG29: 2 | BP29: 41451
A30: 41452 | BP30: 41452
A31: 41453 | BP31: 41453
A32: 41456 | AG32: 1 | BP32: 41456
A33: 41457 | BK33: 0.26 | BP33: 41457
A34: 41458 | P34: 2.9995522 | BP34: 41458
A35: 41459 | BA35: 2.7 | BP35: 41459
A36: 41460 | BP36: 41460
A37: 41463 | L37: 0.40639654 | M37: 5.291015 | S37: 2 | AC37: 0.8 | AW37: 5.5 | BP37: 41463
A38: 41464 | BB38: 2.0094496 | BP38: 41464
A39: 41465 | BP39: 41465
A40: 41466 | BP40: 41466
A41: 41467 | BP41: 41467
A42: 41470 | W42: 4.8858785 | BP42: 41470
A43: 41471 | Z43: 8.999811 | BP43: 41471
...

Sheet 標準化後權重
A1: date | B1: 1101 | C1: 1216 | D1: 1301 | E1: 1303 | F1: 1326 | G1: 1590 | H1: 2002 | I1: 2059 | J1: 2207 | K1: 2301 | L1: 2303 | M1: 2308 | N1: 2317 | O1: 2327 | P1: 2330 | Q1: 2345 | R1: 2357 | S1: 2360 | T1: 2379 | U1: 2382 | V1: 2383 | W1: 2395 | X1: 2408 | Y1: 2412 | Z1: 2454 | AA1: 2603 | AB1: 2609 | AC1: 2615 | AD1: 2618 | AE1: 2801 | AF1: 2880 | AG1: 2881 | AH1: 2882 | AI1: 2883 | AJ1: 2884 | AK1: 2885 | AL1: 2886 | AM1: 2887 | AN1: 2888 | AO1: 2890 | AP1: 2891 | AQ1: 2892 | AR1: 2912 | AS1: 3008 | AT1: 3017 | AU1: 3034 | AV1: 3037 | AW1: 3045 | AX1: 3231 | AY1: 3293 | AZ1: 3443 | BA1: 3529 | BB1: 3653 | BC1: 3661 | BD1: 3711 | BE1: 4904 | BF1: 4938 | BG1: 5871 | BH1: 5876 | BI1: 5880 | BJ1: 6488 | BK1: 6505 | BL1: 6669 | BM1: 6919 | BN1: 8069
A2: 2024-01-03 | BO2: =SUM(B2:BN2) -> 0
A3: 2024-01-04 | B3: =投資後權重!B3/投資後權重!$BT3 -> 0.0085325012 | C3: =投資後權重!C3/投資後權重!$BT3 -> 0.013259478 | D3: =投資後權重!D3/投資後權重!$BT3 -> 0.01604316 | E3: =投資後權重!E3/投資後權重!$BT3 -> 0.016745706 | F3: =投資後權重!F3/投資後權重!$BT3 -> 0.011526875 | G3: =投資後權重!G3/投資後權重!$BT3 -> 0 | H3: =投資後權重!H3/投資後權重!$BT3 -> 0.013555312 | I3: =投資後權重!I3/投資後權重!$BT3 -> 0 | ... BN3: =投資後權重!BN3/投資後權重!$BT3 -> 0 | BO3: =SUM(B3:BN3) -> 1
A4: 2024-01-05 | B4: =投資後權重!B4/投資後權重!$BT4 -> 0.0086003364 | C4: =投資後權重!C4/投資後權重!$BT4 -> 0.013361593 | D4: =投資後權重!D4/投資後權重!$BT4 -> 0.016058968 | E4: =投資後權重!E4/投資後權重!$BT4 -> 0.016753895 | F4: =投資後權重!F4/投資後權重!$BT4 -> 0.011548848 | G4: =投資後權重!G4/投資後權重!$BT4 -> 0 | H4: =投資後權重!H4/投資後權重!$BT4 -> 0.013603415 | I4: =投資後權重!I4/投資後權重!$BT4 -> 0 | ... BN4: =投資後權重!BN4/投資後權重!$BT4 -> 0 | BO4: =SUM(B4:BN4) -> 1
A5: 2024-01-08 | B5: =投資後權重!B5/投資後權重!$BT5 -> 0.0085387817 | C5: =投資後權重!C5/投資後權重!$BT5 -> 0.013341245 | D5: =投資後權重!D5/投資後權重!$BT5 -> 0.015990582 | E5: =投資後權重!E5/投資後權重!$BT5 -> 0.016784584 | F5: =投資後權重!F5/投資後權重!$BT5 -> 0.011499668 | G5: =投資後權重!G5/投資後權重!$BT5 -> 0 | H5: =投資後權重!H5/投資後權重!$BT5 -> 0.013444022 | I5: =投資後權重!I5/投資後權重!$BT5 -> 0 | ... BN5: =投資後權重!BN5/投資後權重!$BT5 -> 0 | BO5: =SUM(B5:BN5) -> 1
A6: 2024-01-09 | B6: =投資後權重!B6/投資後權重!$BT6 -> 0.0084971572 | C6: =投資後權重!C6/投資後權重!$BT6 -> 0.013262724 | D6: =投資後權重!D6/投資後權重!$BT6 -> 0.015903626 | E6: =投資後權重!E6/投資後權重!$BT6 -> 0.016622138 | F6: =投資後權重!F6/投資後權重!$BT6 -> 0.011473086 | G6: =投資後權重!G6/投資後權重!$BT6 -> 0 | H6: =投資後權重!H6/投資後權重!$BT6 -> 0.01320316 | I6: =投資後權重!I6/投資後權重!$BT6 -> 0 | ... BN6: =投資後權重!BN6/投資後權重!$BT6 -> 0 | BO6: =SUM(B6:BN6) -> 1
A7: 2024-01-10 | B7: =投資後權重!B7/投資後權重!$BT7 -> 0.0084400539 | C7: =投資後權重!C7/投資後權重!$BT7 -> 0.013310412 | D7: =投資後權重!D7/投資後權重!$BT7 -> 0.015837402 | E7: =投資後權重!E7/投資後權重!$BT7 -> 0.016528156 | F7: =投資後權重!F7/投資後權重!$BT7 -> 0.011419649 | G7: =投資後權重!G7/投資後權重!$BT7 -> 0 | H7: =投資後權重!H7/投資後權重!$BT7 -> 0.013174188 | I7: =投資後權重!I7/投資後權重!$BT7 -> 0 | ... BN7: =投資後權重!BN7/投資後權重!$BT7 -> 0 | BO7: =SUM(B7:BN7) -> 1
A8: 2024-01-11 | B8: =投資後權重!B8/投資後權重!$BT8 -> 0.0084049025 | C8: =投資後權重!C8/投資後權重!$BT8 -> 0.013218411 | D8: =投資後權重!D8/投資後權重!$BT8 -> 0.015546136 | E8: =投資後權重!E8/投資後權重!$BT8 -> 0.016204135 | F8: =投資後權重!F8/投資後權重!$BT8 -> 0.011372088 | G8: =投資後權重!G8/投資後權重!$BT8 -> 0 | H8: =投資後權重!H8/投資後權重!$BT8 -> 0.013093944 | I8: =投資後權重!I8/投資後權重!$BT8 -> 0 | ... BN8: =投資後權重!BN8/投資後權重!$BT8 -> 0 | BO8: =SUM(B8:BN8) -> 1
A9: 2024-01-12 | B9: =投資後權重!B9/投資後權重!$BT9 -> 0.0084230558 | C9: =投資後權重!C9/投資後權重!$BT9 -> 0.013282221 | D9: =投資後權重!D9/投資後權重!$BT9 -> 0.015577128 | E9: =投資後權重!E9/投資後權重!$BT9 -> 0.016342754 | F9: =投資後權重!F9/投資後權重!$BT9 -> 0.011342022 | G9: =投資後權重!G9/投資後權重!$BT9 -> 0 | H9: =投資後權重!H9/投資後權重!$BT9 -> 0.013102785 | I9: =投資後權重!I9/投資後權重!$BT9 -> 0 | ... BN9: =投資後權重!BN9/投資後權重!$BT9 -> 0 | BO9: =SUM(B9:BN9) -> 1
A10: 2024-01-15 | B10: =投資後權重!B10/投資後權重!$BT10 -> 0.0083960039 | C10: =投資後權重!C10/投資後權重!$BT10 -> 0.013205746 | D10: =投資後權重!D10/投資後權重!$BT10 -> 0.015470788 | E10: =投資後權重!E10/投資後權重!$BT10 -> 0.016236561 | F10: =投資後權重!F10/投資後權重!$BT10 -> 0.011263725 | G10: =投資後權重!G10/投資後權重!$BT10 -> 0 | H10: =投資後權重!H10/投資後權重!$BT10 -> 0.013099516 | I10: =投資後權重!I10/投資後權重!$BT10 -> 0 | ... BN10: =投資後權重!BN10/投資後權重!$BT10 -> 0 | BO10: =SUM(B10:BN10) -> 1
A11: 2024-01-16 | B11: =投資後權重!B11/投資後權重!$BT11 -> 0.0083180068 | C11: =投資後權重!C11/投資後權重!$BT11 -> 0.013195977 | D11: =投資後權重!D11/投資後權重!$BT11 -> 0.015281961 | E11: =投資後權重!E11/投資後權重!$BT11 -> 0.015986788 | F11: =投資後權重!F11/投資後權重!$BT11 -> 0.010897286 | G11: =投資後權重!G11/投資後權重!$BT11 -> 0 | H11: =投資後權重!H11/投資後權重!$BT11 -> 0.012964982 | I11: =投資後權重!I11/投資後權重!$BT11 -> 0 | ... BN11: =投資後權重!BN11/投資後權重!$BT11 -> 0 | BO11: =SUM(B11:BN11) -> 1
A12: 2024-01-17 | B12: =投資後權重!B12/投資後權重!$BT12 -> 0.0082361727 | C12: =投資後權重!C12/投資後權重!$BT12 -> 0.013181447 | D12: =投資後權重!D12/投資後權重!$BT12 -> 0.015082451 | E12: =投資後權重!E12/投資後權重!$BT12 -> 0.015728721 | F12: =投資後權重!F12/投資後權重!$BT12 -> 0.010792546 | G12: =投資後權重!G12/投資後權重!$BT12 -> 0 | H12: =投資後權重!H12/投資後權重!$BT12 -> 0.012908306 | I12: =投資後權重!I12/投資後權重!$BT12 -> 0 | ... BN12: =投資後權重!BN12/投資後權重!$BT12 -> 0 | BO12: =SUM(B12:BN12) -> 1
A13: 2024-01-18 | B13: =投資後權重!B13/投資後權重!$BT13 -> 0.0081529191 | C13: =投資後權重!C13/投資後權重!$BT13 -> 0.013258454 | D13: =投資後權重!D13/投資後權重!$BT13 -> 0.01485363 | E13: =投資後權重!E13/投資後權重!$BT13 -> 0.0156426 | F13: =投資後權重!F13/投資後權重!$BT13 -> 0.010733452 | G13: =投資後權重!G13/投資後權重!$BT13 -> 0 | H13: =投資後權重!H13/投資後權重!$BT13 -> 0.012837628 | I13: =投資後權重!I13/投資後權重!$BT13 -> 0 | ... BN13: =投資後權重!BN13/投資後權重!$BT13 -> 0 | BO13: =SUM(B13:BN13) -> 1
A14: 2024-01-19 | B14: =投資後權重!B14/投資後權重!$BT14 -> 0.0079956416 | C14: =投資後權重!C14/投資後權重!$BT14 -> 0.012934586 | D14: =投資後權重!D14/投資後權重!$BT14 -> 0.014429996 | E14: =投資後權重!E14/投資後權重!$BT14 -> 0.01514987 | F14: =投資後權重!F14/投資後權重!$BT14 -> 0.010431343 | G14: =投資後權重!G14/投資後權重!$BT14 -> 0 | H14: =投資後權重!H14/投資後權重!$BT14 -> 0.012378648 | I14: =投資後權重!I14/投資後權重!$BT14 -> 0 | ... BN14: =投資後權重!BN14/投資後權重!$BT14 -> 0 | BO14: =SUM(B14:BN14) -> 1
... A60: 2024-04-08 | B60: =投資後權重!B60/投資後權重!$BT60 -> 0.0068722832 | C60: =投資後權重!C60/投資後權重!$BT60 -> 0.01176002 | D60: =投資後權重!D60/投資後權重!$BT60 -> 0.012301246 | E60: =投資後權重!E60/投資後權重!$BT60 -> 0.012560985 | F60: =投資後權重!F60/投資後權重!$BT60 -> 0.0088648267 | G60: =投資後權重!G60/投資後權重!$BT60 -> 0 | H60: =投資後權重!H60/投資後權重!$BT60 -> 0.010823969 | I60: =投資後權重!I60/投資後權重!$BT60 -> 0 | ... BN60: =投資後權重!BN60/投資後權重!$BT60 -> 0 | BO60: =SUM(B60:BN60) -> 1
A61: 2024-04-09 | B61: 0.0072467011 | C61: 0.012526012 | D61: 0.013081707 | E61: 0.013417859 | F61: 0.0093926758 | G61: 0.0066499733 | H61: 0.011721574 | J61: 0.010207682 | K61: 0.0066083935 | L61: 0.018721869 | M61: 0.024537704 | N61: 0.060022219 | O61: 0.0073615461 | P61: 0.31038466 | Q61: 0.0074754551 | R61: 0.0090950253 | T61: 0.0083204093 | U61: 0.033010142 | W61: 0.0095489591 | Y61: 0.027766589 | Z61: 0.054301986 | AA61: 0.010207572 | AF61: 0.0090895577 | AG61: 0.029230429 | AH61: 0.02294932 | AI61: 0.0074554494 | AJ61: 0.012192557 | AK61: 0.011249541 | AL61: 0.016651098 | AM61: 0.0070005865 | AO61: 0.0076118572 | AP61: 0.018746236 | AQ61: 0.010698261 | AR61: 0.0080926945 | AS61: 0.0090817807 | AU61: 0.010564784 | AV61: 0.0084273264 | AW61: 0.011107988 | AX61: 0.010756844 | BC61: 0.0071433209 | BD61: 0.020182121 | BE61: 0.0083375833 | BF61: 0.0077811782 | BG61: 0.0089739567 | BH61: 0.0064837742 | BI61: 0.011053333 | BJ61: 0.0071336697 | BK61: 0.020096206 | BL61: 0.012739126 | BN61: 0.007562708
A62: 2024-04-10 | B62: =投資後權重!B62/投資後權重!$BT62 -> 0.0068492456 | C62: =投資後權重!C62/投資後權重!$BT62 -> 0.01173077 | D62: =投資後權重!D62/投資後權重!$BT62 -> 0.012385267 | E62: =投資後權重!E62/投資後權重!$BT62 -> 0.012494328 | F62: =投資後權重!F62/投資後權重!$BT62 -> 0.0088854203 | G62: =投資後權重!G62/投資後權重!$BT62 -> 0 | H62: =投資後權重!H62/投資後權重!$BT62 -> 0.010911462 | I62: =投資後權重!I62/投資後權重!$BT62 -> 0 | ... BN62: =投資後權重!BN62/投資後權重!$BT62 -> 0 | BO62: =SUM(B62:BN62) -> 1
A63: 2024-04-11 | B63: =投資後權重!B63/投資後權重!$BT63 -> 0.006790513 | C63: =投資後權重!C63/投資後權重!$BT63 -> 0.011737865 | D63: =投資後權重!D63/投資後權重!$BT63 -> 0.012203424 | E63: =投資後權重!E63/投資後權重!$BT63 -> 0.012266 | F63: =投資後權重!F63/投資後權重!$BT63 -> 0.0087957056 | G63: =投資後權重!G63/投資後權重!$BT63 -> 0 | H63: =投資後權重!H63/投資後權重!$BT63 -> 0.010790115 | I63: =投資後權重!I63/投資後權重!$BT63 -> 0 | ... BN63: =投資後權重!BN63/投資後權重!$BT63 -> 0 | BO63: =SUM(B63:BN63) -> 1
A64: 2024-04-12 | B64: =投資後權重!B64/投資後權重!$BT64 -> 0.0067832448 | C64: =投資後權重!C64/投資後權重!$BT64 -> 0.0118599 | D64: =投資後權重!D64/投資後權重!$BT64 -> 0.012058473 | E64: =投資後權重!E64/投資後權重!$BT64 -> 0.012372084 | F64: =投資後權重!F64/投資後權重!$BT64 -> 0.0088090055 | G64: =投資後權重!G64/投資後權重!$BT64 -> 0 | H64: =投資後權重!H64/投資後權重!$BT64 -> 0.010652609 | I64: =投資後權重!I64/投資後權重!$BT64 -> 0 | ... BN64: =投資後權重!BN64/投資後權重!$BT64 -> 0 | BO64: =SUM(B64:BN64) -> 1
A65: 2024-04-15 | B65: =投資後權重!B65/投資後權重!$BT65 -> 0.0069139908 | C65: =投資後權重!C65/投資後權重!$BT65 -> 0.012016778 | D65: =投資後權重!D65/投資後權重!$BT65 -> 0.012216355 | E65: =投資後權重!E65/投資後權重!$BT65 -> 0.012508346 | F65: =投資後權重!F65/投資後權重!$BT65 -> 0.0088886811 | G65: =投資後權重!G65/投資後權重!$BT65 -> 0 | H65: =投資後權重!H65/投資後權重!$BT65 -> 0.010677117 | I65: =投資後權重!I65/投資後權重!$BT65 -> 0 | ... BN65: =投資後權重!BN65/投資後權重!$BT65 -> 0 | BO65: =SUM(B65:BN65) -> 1
A66: 2024-04-16 | B66: =投資後權重!B66/投資後權重!$BT66 -> 0.0071272133 | C66: =投資後權重!C66/投資後權重!$BT66 -> 0.011994979 | D66: =投資後權重!D66/投資後權重!$BT66 -> 0.012265687 | E66: =投資後權重!E66/投資後權重!$BT66 -> 0.012472324 | F66: =投資後權重!F66/投資後權重!$BT66 -> 0.0089518737 | G66: =投資後權重!G66/投資後權重!$BT66 -> 0 | H66: =投資後權重!H66/投資後權重!$BT66 -> 0.01083839 | I66: =投資後權重!I66/投資後權重!$BT66 -> 0 | ... BN66: =投資後權重!BN66/投資後權重!$BT66 -> 0 | BO66: =SUM(B66:BN66) -> 1
A67: 2024-04-17 | B67: =投資後權重!B67/投資後權重!$BT67 -> 0.0070802057 | C67: =投資後權重!C67/投資後權重!$BT67 -> 0.011985943 | D67: =投資後權重!D67/投資後權重!$BT67 -> 0.012074532 | E67: =投資後權重!E67/投資後權重!$BT67 -> 0.012203228 | F67: =投資後權重!F67/投資後權重!$BT67 -> 0.0087891648 | G67: =投資後權重!G67/投資後權重!$BT67 -> 0 | H67: =投資後權重!H67/投資後權重!$BT67 -> 0.010789208 | I67: =投資後權重!I67/投資後權重!$BT67 -> 0 | ... BN67: =投資後權重!BN67/投資後權重!$BT67 -> 0 | BO67: =SUM(B67:BN67) -> 1
A68: 2024-04-18 | B68: =投資後權重!B68/投資後權重!$BT68 -> 0.0070670773 | C68: =投資後權重!C68/投資後權重!$BT68 -> 0.012167224 | D68: =投資後權重!D68/投資後權重!$BT68 -> 0.012086961 | E68: =投資後權重!E68/投資後權重!$BT68 -> 0.012338877 | F68: =投資後權重!F68/投資後權重!$BT68 -> 0.0087594534 | G68: =投資後權重!G68/投資後權重!$BT68 -> 0 | H68: =投資後權重!H68/投資後權重!$BT68 -> 0.01090666 | I68: =投資後權重!I68/投資後權重!$BT68 -> 0 | ... BN68: =投資後權重!BN68/投資後權重!$BT68 -> 0 | BO68: =SUM(B68:BN68) -> 1
A69: 2024-04-19 | B69: =投資後權重!B69/投資後權重!$BT69 -> 0.0072061951 | C69: =投資後權重!C69/投資後權重!$BT69 -> 0.012546073 | D69: =投資後權重!D69/投資後權重!$BT69 -> 0.012409562 | E69: =投資後權重!E69/投資後權重!$BT69 -> 0.012672669 | F69: =投資後權重!F69/投資後權重!$BT69 -> 0.0089229293 | G69: =投資後權重!G69/投資後權重!$BT69 -> 0 | H69: =投資後權重!H69/投資後權重!$BT69 -> 0.011204253 | I69: =投資後權重!I69/投資後權重!$BT69 -> 0 | ... BN69: =投資後權重!BN69/投資後權重!$BT69 -> 0 | BO69: =SUM(B69:BN69) -> 1
A70: 2024-04-22 | B70: =投資後權重!B70/投資後權重!$BT70 -> 0.0073535769 | C70: =投資後權重!C70/投資後權重!$BT70 -> 0.013046566 | D70: =投資後權重!D70/投資後權重!$BT70 -> 0.012911947 | E70: =投資後權重!E70/投資後權重!$BT70 -> 0.013224675 | F70: =投資後權重!F70/投資後權重!$BT70 -> 0.0093983749 | G70: =投資後權重!G70/投資後權重!$BT70 -> 0 | H70: =投資後權重!H70/投資後權重!$BT70 -> 0.011337727 | I70: =投資後權重!I70/投資後權重!$BT70 -> 0 | ... BN70: =投資後權重!BN70/投資後權重!$BT70 -> 0 | BO70: =SUM(B70:BN70) -> 1
A71: 2024-04-23 | B71: =投資後權重!B71/投資後權重!$BT71 -> 0.0072400167 | C71: =投資後權重!C71/投資後權重!$BT71 -> 0.012862326 | D71: =投資後權重!D71/投資後權重!$BT71 -> 0.012700512 | E71: =投資後權重!E71/投資後權重!$BT71 -> 0.012983677 | F71: =投資後權重!F71/投資後權重!$BT71 -> 0.0092908993 | G71: =投資後權重!G71/投資後權重!$BT71 -> 0 | H71: =投資後權重!H71/投資後權重!$BT71 -> 0.011317218 | I71: =投資後權重!I71/投資後權重!$BT71 -> 0 | ... BN71: =投資後權重!BN71/投資後權重!$BT71 -> 0 | BO71: =SUM(B71:BN71) -> 1
A72: 2024-04-24 | B72: =投資後權重!B72/投資後權重!$BT72 -> 0.0069955766 | C72: =投資後權重!C72/投資後權重!$BT72 -> 0.012282066 | D72: =投資後權重!D72/投資後權重!$BT72 -> 0.012294444 | E72: =投資後權重!E72/投資後權重!$BT72 -> 0.012556569 | F72: =投資後權重!F72/投資後權重!$BT72 -> 0.0090166087 | G72: =投資後權重!G72/投資後權重!$BT72 -> 0 | H72: =投資後權重!H72/投資後權重!$BT72 -> 0.010958869 | I72: =投資後權重!I72/投資後權重!$BT72 -> 0 | ... BN72: =投資後權重!BN72/投資後權重!$BT72 -> 0 | BO72: =SUM(B72:BN72) -> 1
A73: 2024-04-25 | B73: =投資後權重!B73/投資後權重!$BT73 -> 0.0070821652 | C73: =投資後權重!C73/投資後權重!$BT73 -> 0.012346359 | D73: =投資後權重!D73/投資後權重!$BT73 -> 0.012341381 | E73: =投資後權重!E73/投資後權重!$BT73 -> 0.012635709 | F73: =投資後權重!F73/投資後權重!$BT73 -> 0.0090371182 | G73: =投資後權重!G73/投資後權重!$BT73 -> 0 | H73: =投資後權重!H73/投資後權重!$BT73 -> 0.011056446 | I73: =投資後權重!I73/投資後權重!$BT73 -> 0 | ... BN73: =投資後權重!BN73/投資後權重!$BT73 -> 0 | BO73: =SUM(B73:BN73) -> 1
... A121: 2024-07-04 | B121: =投資後權重!B121/投資後權重!$BT121 -> 0.0062645412 | C121: =投資後權重!C121/投資後權重!$BT121 -> 0.01132267 | D121: =投資後權重!D121/投資後權重!$BT121 -> 0.0086775865 | E121: =投資後權重!E121/投資後權重!$BT121 -> 0.0092814156 | F121: =投資後權重!F121/投資後權重!$BT121 -> 0.0068524463 | G121: =投資後權重!G121/投資後權重!$BT121 -> 0 | H121: =投資後權重!H121/投資後權重!$BT121 -> 0.008772319 | I121: =投資後權重!I121/投資後權重!$BT121 -> 0 | ... BN121: =投資後權重!BN121/投資後權重!$BT121 -> 0 | BO121: =SUM(B121:BN121) -> 1
A122: 2024-07-05 | B122: 0.0068137234 | C122: 0.012509133 | D122: 0.0096917117 | E122: 0.010256364 | F122: 0.0077101065 | H122: 0.0098051607 | J122: 0.0092313148 | K122: 0.0064925371 | L122: 0.016442934 | M122: 0.026545581 | N122: 0.076792897 | O122: 0.0082667184 | P122: 0.3088774 | Q122: 0.0085319311 | R122: 0.0090240685 | T122: 0.0077100644 | U122: 0.032470778 | W122: 0.0084757623 | Y122: 0.023440966 | Z122: 0.055809774 | AA122: 0.010346192 | AB122: 0.0065970366 | AC122: 0.0061447003 | AF122: 0.0097571526 | AG122: 0.033057337 | AH122: 0.025217321 | AI122: 0.0075245991 | AJ122: 0.012046902 | AK122: 0.011133655 | AL122: 0.016028816 | AM122: 0.0069207745 | AO122: 0.0086571285 | AP122: 0.021309867 | AQ122: 0.010296585 | AR122: 0.0076118212 | AS122: 0.010311216 | AT122: 0.0080170238 | AU122: 0.0099049416 | AV122: 0.0072306615 | AW122: 0.011483244 | AX122: 0.008277595 | BD122: 0.018494342 | BE122: 0.0086630328 | BF122: 0.0074036001 | BG122: 0.00734505 | BI122: 0.010286284 | BJ122: 0.0073427572 | BK122: 0.016485582 | BL122: 0.012988246 | BN122: 0.0082176151
A123: 2024-07-08 | B123: =投資後權重!B123/投資後權重!$BT123 -> 0.0062123906 | C123: =投資後權重!C123/投資後權重!$BT123 -> 0.011016567 | D123: =投資後權重!D123/投資後權重!$BT123 -> 0.0085524108 | E123: =投資後權重!E123/投資後權重!$BT123 -> 0.0090477012 | F123: =投資後權重!F123/投資後權重!$BT123 -> 0.0066730796 | G123: =投資後權重!G123/投資後權重!$BT123 -> 0 | H123: =投資後權重!H123/投資後權重!$BT123 -> 0.0085861508 | I123: =投資後權重!I123/投資後權重!$BT123 -> 0 | ... BN123: =投資後權重!BN123/投資後權重!$BT123 -> 0 | BO123: =SUM(B123:BN123) -> 1
A124: 2024-07-09 | B124: =投資後權重!B124/投資後權重!$BT124 -> 0.0060837826 | C124: =投資後權重!C124/投資後權重!$BT124 -> 0.011110059 | D124: =投資後權重!D124/投資後權重!$BT124 -> 0.0083762095 | E124: =投資後權重!E124/投資後權重!$BT124 -> 0.0088794459 | F124: =投資後權重!F124/投資後權重!$BT124 -> 0.0065623084 | G124: =投資後權重!G124/投資後權重!$BT124 -> 0 | H124: =投資後權重!H124/投資後權重!$BT124 -> 0.0084475495 | I124: =投資後權重!I124/投資後權重!$BT124 -> 0 | ... BN124: =投資後權重!BN124/投資後權重!$BT124 -> 0 | BO124: =SUM(B124:BN124) -> 1
A125: 2024-07-10 | B125: =投資後權重!B125/投資後權重!$BT125 -> 0.0060415624 | C125: =投資後權重!C125/投資後權重!$BT125 -> 0.011081848 | D125: =投資後權重!D125/投資後權重!$BT125 -> 0.0082816514 | E125: =投資後權重!E125/投資後權重!$BT125 -> 0.0087655906 | F125: =投資後權重!F125/投資後權重!$BT125 -> 0.0063499506 | G125: =投資後權重!G125/投資後權重!$BT125 -> 0 | H125: =投資後權重!H125/投資後權重!$BT125 -> 0.0083716201 | I125: =投資後權重!I125/投資後權重!$BT125 -> 0 | ... BN125: =投資後權重!BN125/投資後權重!$BT125 -> 0 | BO125: =SUM(B125:BN125) -> 1
A126: 2024-07-11 | B126: =投資後權重!B126/投資後權重!$BT126 -> 0.0059675111 | C126: =投資後權重!C126/投資後權重!$BT126 -> 0.010984503 | D126: =投資後權重!D126/投資後權重!$BT126 -> 0.008204061 | E126: =投資後權重!E126/投資後權重!$BT126 -> 0.0087328186 | F126: =投資後權重!F126/投資後權重!$BT126 -> 0.0063214197 | G126: =投資後權重!G126/投資後權重!$BT126 -> 0 | H126: =投資後權重!H126/投資後權重!$BT126 -> 0.0082204396 | I126: =投資後權重!I126/投資後權重!$BT126 -> 0 | ... BN126: =投資後權重!BN126/投資後權重!$BT126 -> 0 | BO126: =SUM(B126:BN126) -> 1
A127: 2024-07-12 | B127: =投資後權重!B127/投資後權重!$BT127 -> 0.0061484089 | C127: =投資後權重!C127/投資後權重!$BT127 -> 0.011277716 | D127: =投資後權重!D127/投資後權重!$BT127 -> 0.0085360832 | E127: =投資後權重!E127/投資後權重!$BT127 -> 0.0092021488 | F127: =投資後權重!F127/投資後權重!$BT127 -> 0.0066039707 | G127: =投資後權重!G127/投資後權重!$BT127 -> 0 | H127: =投資後權重!H127/投資後權重!$BT127 -> 0.0084384395 | I127: =投資後權重!I127/投資後權重!$BT127 -> 0 | ... BN127: =投資後權重!BN127/投資後權重!$BT127 -> 0 | BO127: =SUM(B127:BN127) -> 1
A128: 2024-07-15 | B128: =投資後權重!B128/投資後權重!$BT128 -> 0.0061396873 | C128: =投資後權重!C128/投資後權重!$BT128 -> 0.011416846 | D128: =投資後權重!D128/投資後權重!$BT128 -> 0.0084727502 | E128: =投資後權重!E128/投資後權重!$BT128 -> 0.0091466168 | F128: =投資後權重!F128/投資後權重!$BT128 -> 0.0065759595 | G128: =投資後權重!G128/投資後權重!$BT128 -> 0 | H128: =投資後權重!H128/投資後權重!$BT128 -> 0.008573452 | I128: =投資後權重!I128/投資後權重!$BT128 -> 0 | ... BN128: =投資後權重!BN128/投資後權重!$BT128 -> 0 | BO128: =SUM(B128:BN128) -> 1
A129: 2024-07-16 | B129: =投資後權重!B129/投資後權重!$BT129 -> 0.0061174412 | C129: =投資後權重!C129/投資後權重!$BT129 -> 0.011148719 | D129: =投資後權重!D129/投資後權重!$BT129 -> 0.0084149789 | E129: =投資後權重!E129/投資後權重!$BT129 -> 0.0089626681 | F129: =投資後權重!F129/投資後權重!$BT129 -> 0.0065560851 | G129: =投資後權重!G129/投資後權重!$BT129 -> 0 | H129: =投資後權重!H129/投資後權重!$BT129 -> 0.008420523 | I129: =投資後權重!I129/投資後權重!$BT129 -> 0 | ... BN129: =投資後權重!BN129/投資後權重!$BT129 -> 0 | BO129: =SUM(B129:BN129) -> 1
A130: 2024-07-17 | B130: =投資後權重!B130/投資後權重!$BT130 -> 0.0062511271 | C130: =投資後權重!C130/投資後權重!$BT130 -> 0.011263497 | D130: =投資後權重!D130/投資後權重!$BT130 -> 0.0089431726 | E130: =投資後權重!E130/投資後權重!$BT130 -> 0.0093437052 | F130: =投資後權重!F130/投資後權重!$BT130 -> 0.0068163588 | G130: =投資後權重!G130/投資後權重!$BT130 -> 0 | H130: =投資後權重!H130/投資後權重!$BT130 -> 0.0086094243 | I130: =投資後權重!I130/投資後權重!$BT130 -> 0 | ... BN130: =投資後權重!BN130/投資後權重!$BT130 -> 0 | BO130: =SUM(B130:BN130) -> 1
A131: 2024-07-18 | B131: =投資後權重!B131/投資後權重!$BT131 -> 0.0064103911 | C131: =投資後權重!C131/投資後權重!$BT131 -> 0.011801981 | D131: =投資後權重!D131/投資後權重!$BT131 -> 0.0091978594 | E131: =投資後權重!E131/投資後權重!$BT131 -> 0.0095557021 | F131: =投資後權重!F131/投資後權重!$BT131 -> 0.0071317378 | G131: =投資後權重!G131/投資後權重!$BT131 -> 0 | H131: =投資後權重!H131/投資後權重!$BT131 -> 0.008808889 | I131: =投資後權重!I131/投資後權重!$BT131 -> 0 | ... BN131: =投資後權重!BN131/投資後權重!$BT131 -> 0 | BO131: =SUM(B131:BN131) -> 1
A132: 2024-07-19 | B132: =投資後權重!B132/投資後權重!$BT132 -> 0.0065161833 | C132: =投資後權重!C132/投資後權重!$BT132 -> 0.011997069 | D132: =投資後權重!D132/投資後權重!$BT132 -> 0.0092954319 | E132: =投資後權重!E132/投資後權重!$BT132 -> 0.0097117409 | F132: =投資後權重!F132/投資後權重!$BT132 -> 0.0071916526 | G132: =投資後權重!G132/投資後權重!$BT132 -> 0 | H132: =投資後權重!H132/投資後權重!$BT132 -> 0.0089485377 | I132: =投資後權重!I132/投資後權重!$BT132 -> 0 | ... BN132: =投資後權重!BN132/投資後權重!$BT132 -> 0 | BO132: =SUM(B132:BN132) -> 1
...

Sheet 驗證
A1: date | B1: 1101 | C1: 1216 | D1: 1301 | E1: 1303 | F1: 1326 | G1: 1590 | H1: 2002 | I1: 2059 | J1: 2207 | K1: 2301 | L1: 2303 | M1: 2308 | N1: 2317 | O1: 2327 | P1: 2330 | Q1: 2345 | R1: 2357 | S1: 2360 | T1: 2379 | U1: 2382 | V1: 2383 | W1: 2395 | X1: 2408 | Y1: 2412 | Z1: 2454 | AA1: 2603 | AB1: 2609 | AC1: 2615 | AD1: 2618 | AE1: 2801 | AF1: 2880 | AG1: 2881 | AH1: 2882 | AI1: 2883 | AJ1: 2884 | AK1: 2885 | AL1: 2886 | AM1: 2887 | AN1: 2888 | AO1: 2890 | AP1: 2891 | AQ1: 2892 | AR1: 2912 | AS1: 3008 | AT1: 3017 | AU1: 3034 | AV1: 3037 | AW1: 3045 | AX1: 3231 | AY1: 3293 | AZ1: 3443 | BA1: 3529 | BB1: 3653 | BC1: 3661 | BD1: 3711 | BE1: 4904 | BF1: 4938 | BG1: 5871 | BH1: 5876 | BI1: 5880 | BJ1: 6488 | BK1: 6505 | BL1: 6669 | BM1: 6919 | BN1: 8069
A2: 2024-01-03
A3: 2024-01-04 | B3: =每日權重!B3-標準化後權重!B3 -> 5.4837829e-07 | C3: =每日權重!C3-標準化後權重!C3 -> 8.5217802e-07 | D3: =每日權重!D3-標準化後權重!D3 -> 1.0310834e-06 | E3: =每日權重!E3-標準化後權重!E3 -> 1.0762356e-06 | F3: =每日權重!F3-標準化後權重!F3 -> 7.4082475e-07 | G3: =每日權重!G3-標準化後權重!G3 -> 0 | H3: =每日權重!H3-標準化後權重!H3 -> 8.7119104e-07 | I3: =每日權重!I3-標準化後權重!I3 -> 0 | ... BN3: =每日權重!BN3-標準化後權重!BN3 -> 0
A4: 2024-01-05 | B4: =每日權重!B4-標準化後權重!B4 -> 5.505152e-07 | C4: =每日權重!C4-標準化後權重!C4 -> 8.5528751e-07 | D4: =每日權重!D4-標準化後權重!D4 -> 1.0279489e-06 | E4: =每日權重!E4-標準化後權重!E4 -> 1.0724318e-06 | F4: =每日權重!F4-標準化後權重!F4 -> 7.3925204e-07 | G4: =每日權重!G4-標準化後權重!G4 -> 0 | H4: =每日權重!H4-標準化後權重!H4 -> 8.7076673e-07 | I4: =每日權重!I4-標準化後權重!I4 -> 0 | ... BN4: =每日權重!BN4-標準化後權重!BN4 -> 0
A5: 2024-01-08 | B5: =每日權重!B5-標準化後權重!B5 -> 5.4365636e-07 | C5: =每日權重!C5-標準化後權重!C5 -> 8.494248e-07 | D5: =每日權重!D5-標準化後權重!D5 -> 1.0181056e-06 | E5: =每日權重!E5-標準化後權重!E5 -> 1.068659e-06 | F5: =每日權重!F5-標準化後權重!F5 -> 7.3217325e-07 | G5: =每日權重!G5-標準化後權重!G5 -> 0 | H5: =每日權重!H5-標準化後權重!H5 -> 8.5596846e-07 | I5: =每日權重!I5-標準化後權重!I5 -> 0 | ... BN5: =每日權重!BN5-標準化後權重!BN5 -> 0
A6: 2024-01-09 | B6: =每日權重!B6-標準化後權重!B6 -> 5.4624042e-07 | C6: =每日權重!C6-標準化後權重!C6 -> 8.5259524e-07 | D6: =每日權重!D6-標準化後權重!D6 -> 1.0223659e-06 | E6: =每日權重!E6-標準化後權重!E6 -> 1.0685555e-06 | F6: =每日權重!F6-標準化後權重!F6 -> 7.3754823e-07 | G6: =每日權重!G6-標準化後權重!G6 -> 0 | H6: =每日權重!H6-標準化後權重!H6 -> 8.4876617e-07 | I6: =每日權重!I6-標準化後權重!I6 -> 0 | ... BN6: =每日權重!BN6-標準化後權重!BN6 -> 0
A7: 2024-01-10 | B7: =每日權重!B7-標準化後權重!B7 -> 5.4217334e-07 | C7: =每日權重!C7-標準化後權重!C7 -> 8.5503608e-07 | D7: =每日權重!D7-標準化後權重!D7 -> 1.0173652e-06 | E7: =每日權重!E7-標準化後權重!E7 -> 1.0617379e-06 | F7: =每日權重!F7-標準化後權重!F7 -> 7.3357698e-07 | G7: =每日權重!G7-標準化後權重!G7 -> 0 | H7: =每日權重!H7-標準化後權重!H7 -> 8.462853e-07 | I7: =每日權重!I7-標準化後權重!I7 -> 0 | ... BN7: =每日權重!BN7-標準化後權重!BN7 -> 0
A8: 2024-01-11 | B8: =每日權重!B8-標準化後權重!B8 -> 5.3533877e-07 | C8: =每日權重!C8-標準化後權重!C8 -> 8.4192862e-07 | D8: =每日權重!D8-標準化後權重!D8 -> 9.9018987e-07 | E8: =每日權重!E8-標準化後權重!E8 -> 1.0321002e-06 | F8: =每日權重!F8-標準化後權重!F8 -> 7.243296e-07 | G8: =每日權重!G8-標準化後權重!G8 -> 0 | H8: =每日權重!H8-標準化後權重!H8 -> 8.3400085e-07 | I8: =每日權重!I8-標準化後權重!I8 -> 0 | ... BN8: =每日權重!BN8-標準化後權重!BN8 -> 0
A9: 2024-01-12 | B9: =每日權重!B9-標準化後權重!B9 -> 5.4035874e-07 | C9: =每日權重!C9-標準化後權重!C9 -> 8.5208555e-07 | D9: =每日權重!D9-標準化後權重!D9 -> 9.9930923e-07 | E9: =每日權重!E9-標準化後權重!E9 -> 1.0484259e-06 | F9: =每日權重!F9-標準化後權重!F9 -> 7.2761727e-07 | G9: =每日權重!G9-標準化後權重!G9 -> 0 | H9: =每日權重!H9-標準化後權重!H9 -> 8.4057428e-07 | I9: =每日權重!I9-標準化後權重!I9 -> 0 | ... BN9: =每日權重!BN9-標準化後權重!BN9 -> 0
A10: 2024-01-15 | B10: =每日權重!B10-標準化後權重!B10 -> 5.361627e-07 | C10: =每日權重!C10-標準化後權重!C10 -> 8.4330934e-07 | D10: =每日權重!D10-標準化後權重!D10 -> 9.8795324e-07 | E10: =每日權重!E10-標準化後權重!E10 -> 1.036855e-06 | F10: =每日權重!F10-標準化後權重!F10 -> 7.1929326e-07 | G10: =每日權重!G10-標準化後權重!G10 -> 0 | H10: =每日權重!H10-標準化後權重!H10 -> 8.3652559e-07 | I10: =每日權重!I10-標準化後權重!I10 -> 0 | ... BN10: =每日權重!BN10-標準化後權重!BN10 -> 0
A11: 2024-01-16 | B11: =每日權重!B11-標準化後權重!B11 -> 5.2248126e-07 | C11: =每日權重!C11-標準化後權重!C11 -> 8.2888253e-07 | D11: =每日權重!D11-標準化後權重!D11 -> 9.5991005e-07 | E11: =每日權重!E11-標準化後權重!E11 -> 1.0041825e-06 | F11: =每日權重!F11-標準化後權重!F11 -> 6.8449424e-07 | G11: =每日權重!G11-標準化後權重!G11 -> 0 | H11: =每日權重!H11-標準化後權重!H11 -> 8.1437297e-07 | I11: =每日權重!I11-標準化後權重!I11 -> 0 | ... BN11: =每日權重!BN11-標準化後權重!BN11 -> 0
A12: 2024-01-17 | B12: =每日權重!B12-標準化後權重!B12 -> 5.1403033e-07 | C12: =每日權重!C12-標準化後權重!C12 -> 8.2267136e-07 | D12: =每日權重!D12-標準化後權重!D12 -> 9.4131553e-07 | E12: =每日權重!E12-標準化後權重!E12 -> 9.8165007e-07 | F12: =每日權重!F12-標準化後權重!F12 -> 6.7357692e-07 | G12: =每日權重!G12-標準化後權重!G12 -> 0 | H12: =每日權重!H12-標準化後權重!H12 -> 8.0562428e-07 | I12: =每日權重!I12-標準化後權重!I12 -> 0 | ... BN12: =每日權重!BN12-標準化後權重!BN12 -> 0
A13: 2024-01-18 | B13: =每日權重!B13-標準化後權重!B13 -> 5.1641154e-07 | C13: =每日權重!C13-標準化後權重!C13 -> 8.3979964e-07 | D13: =每日權重!D13-標準化後權重!D13 -> 9.4083921e-07 | E13: =每日權重!E13-標準化後權重!E13 -> 9.9081308e-07 | F13: =每日權重!F13-標準化後權重!F13 -> 6.7986429e-07 | G13: =每日權重!G13-標準化後權重!G13 -> 0 | H13: =每日權重!H13-標準化後權重!H13 -> 8.1314421e-07 | I13: =每日權重!I13-標準化後權重!I13 -> 0 | ... BN13: =每日權重!BN13-標準化後權重!BN13 -> 0
A14: 2024-01-19 | B14: =每日權重!B14-標準化後權重!B14 -> 1.3922568e-06 | C14: =每日權重!C14-標準化後權重!C14 -> 2.2522601e-06 | D14: =每日權重!D14-標準化後權重!D14 -> 2.5126513e-06 | E14: =每日權重!E14-標準化後權重!E14 -> 2.6380009e-06 | F14: =每日權重!F14-標準化後權重!F14 -> 1.8163781e-06 | G14: =每日權重!G14-標準化後權重!G14 -> 0 | H14: =每日權重!H14-標準化後權重!H14 -> 2.1554564e-06 | I14: =每日權重!I14-標準化後權重!I14 -> 0 | ... BN14: =每日權重!BN14-標準化後權重!BN14 -> 0
... A479: 2025-12-22 | B479: =每日權重!B479-標準化後權重!B479 -> -0.0037074935 | C479: =每日權重!C479-標準化後權重!C479 -> 0.0013369495 | D479: =每日權重!D479-標準化後權重!D479 -> 0.00079519261 | E479: =每日權重!E479-標準化後權重!E479 -> 0.0014085951 | F479: =每日權重!F479-標準化後權重!F479 -> -0.0030053518 | G479: =每日權重!G479-標準化後權重!G479 -> 0 | H479: =每日權重!H479-標準化後權重!H479 -> 0.00084651661 | I479: =每日權重!I479-標準化後權重!I479 -> 0.0083589568 | ... BN479: =每日權重!BN479-標準化後權重!BN479 -> 0.0050088697

Sheet 每日權重
A1: date | B1: 1101 | C1: 1216 | D1: 1301 | E1: 1303 | F1: 1326 | G1: 1590 | H1: 2002 | I1: 2059 | J1: 2207 | K1: 2301 | L1: 2303 | M1: 2308 | N1: 2317 | O1: 2327 | P1: 2330 | Q1: 2345 | R1: 2357 | S1: 2360 | T1: 2379 | U1: 2382 | V1: 2383 | W1: 2395 | X1: 2408 | Y1: 2412 | Z1: 2454 | AA1: 2603 | AB1: 2609 | AC1: 2615 | AD1: 2618 | AE1: 2801 | AF1: 2880 | AG1: 2881 | AH1: 2882 | AI1: 2883 | AJ1: 2884 | AK1: 2885 | AL1: 2886 | AM1: 2887 | AN1: 2888 | AO1: 2890 | AP1: 2891 | AQ1: 2892 | AR1: 2912 | AS1: 3008 | AT1: 3017 | AU1: 3034 | AV1: 3037 | AW1: 3045 | AX1: 3231 | AY1: 3293 | AZ1: 3443 | BA1: 3529 | BB1: 3653 | BC1: 3661 | BD1: 3711 | BE1: 4904 | BF1: 4938 | BG1: 5871 | BH1: 5876 | BI1: 5880 | BJ1: 6488 | BK1: 6505 | BL1: 6669 | BM1: 6919 | BN1: 8069
A2: 2024-01-03 | B2: 0.0085195677 | C2: 0.013330686 | D2: 0.015977926 | E2: 0.016720322 | F2: 0.011509403 | H2: 0.013534765 | J2: 0.012264334 | K2: 0.0085076765 | L2: 0.020376065 | M2: 0.025419544 | N2: 0.046558253 | O2: 0.007859445 | P2: 0.3 | Q2: 0.0088252038 | R2: 0.011100602 | T2: 0.0074506446 | U2: 0.026565599 | W2: 0.0099233729 | X2: 0.0072787042 | Y2: 0.029917312 | Z2: 0.048995308 | AA2: 0.010596994 | AF2: 0.0096460185 | AG2: 0.029920205 | AH2: 0.023406395 | AI2: 0.0072803111 | AJ2: 0.012887497 | AK2: 0.010990368 | AL2: 0.017888553 | AM2: 0.0077887405 | AO2: 0.0076765775 | AP2: 0.018237576 | AQ2: 0.011818574 | AR2: 0.0089206549 | AS2: 0.011520008 | AU2: 0.0097684658 | AV2: 0.0083325222 | AW2: 0.011834001 | AX2: 0.0087136836 | AZ2: 0.0070627342 | BC2: 0.0082261441 | BD2: 0.017807886 | BE2: 0.0092009017 | BF2: 0.0073548722 | BG2: 0.010888489 | BH2: 0.0071871097 | BI2: 0.012456521 | BJ2: 0.0080310641 | BK2: 0.024400114 | BL2: 0.0095222857
A3: 2024-01-04 | B3: 0.0085330496 | C3: 0.013260331 | D3: 0.016044191 | E3: 0.016746782 | F3: 0.011527616 | H3: 0.013556183 | J3: 0.012158214 | K3: 0.008596883 | L3: 0.020488975 | M3: 0.025417963 | N3: 0.046408811 | O3: 0.0078582631 | P3: 0.30151444 | Q3: 0.0088572085 | R3: 0.010855158 | T3: 0.0075284742 | U3: 0.027229312 | W3: 0.0099390762 | X3: 0.0074198707 | Y3: 0.02971495 | Z3: 0.046518788 | AA3: 0.011024618 | AF3: 0.009661283 | AG3: 0.029873463 | AH3: 0.023313048 | AI3: 0.0072918319 | AJ3: 0.012958313 | AK3: 0.011109872 | AL3: 0.017963218 | AM3: 0.0078010659 | AO3: 0.0077285634 | AP3: 0.018234049 | AQ3: 0.011837277 | AR3: 0.0089515033 | AS3: 0.011387833 | AU3: 0.0096957806 | AV3: 0.0080756999 | AW3: 0.011852727 | AX3: 0.0087928121 | AZ3: 0.0070307771 | BC3: 0.0080478314 | BD3: 0.017906564 | BE3: 0.0092154618 | BF3: 0.0072550271 | BG3: 0.011104522 | BH3: 0.0072297808 | BI3: 0.012547256 | BJ3: 0.0081280009 | BK3: 0.024438726 | BL3: 0.0093685516
A4: 2024-01-05 | B4: 0.0086008869 | C4: 0.013362449 | D4: 0.016059996 | E4: 0.016754968 | F4: 0.011549587 | H4: 0.013604286 | J4: 0.012147368 | K4: 0.0087034006 | L4: 0.020561678 | M4: 0.025550111 | N4: 0.046573488 | O4: 0.00781781 | P4: 0.30049755 | Q4: 0.0088071735 | R4: 0.010893677 | T4: 0.0074640622 | U4: 0.026889217 | W4: 0.0099327845 | X4: 0.0074762245 | Y4: 0.029945687 | Z4: 0.046331715 | AA4: 0.011166817 | AF4: 0.0097176006 | AG4: 0.029837831 | AH4: 0.023474282 | AI4: 0.0073474532 | AJ4: 0.012978994 | AK4: 0.01104682 | AL4: 0.018120001 | AM4: 0.0078287474 | AO4: 0.0077959669 | AP4: 0.018266249 | AQ4: 0.01187928 | AR4: 0.0089832669 | AS4: 0.011191052 | AU4: 0.0096319006 | AV4: 0.0078826562 | AW4: 0.011846678 | AX4: 0.0087678087 | AZ4: 0.0071639418 | BC4: 0.0081363913 | BD4: 0.017899356 | BE4: 0.0092132194 | BF4: 0.0072205282 | BG4: 0.010830413 | BH4: 0.0072789917 | BI4: 0.012591778 | BJ4: 0.0082272815 | BK4: 0.024494673 | BL4: 0.0096558977
A5: 2024-01-08 | B5: 0.0085393253 | C5: 0.013342095 | D5: 0.0159916 | E5: 0.016785653 | F5: 0.0115004 | H5: 0.013444878 | J5: 0.012256911 | K5: 0.0086663348 | L5: 0.020353201 | M5: 0.025566626 | N5: 0.045260356 | O5: 0.0077845158 | P5: 0.30285413 | Q5: 0.0089499261 | R5: 0.010835337 | T5: 0.0074322745 | U5: 0.026588335 | W5: 0.0099594543 | X5: 0.0072849337 | Y5: 0.030067679 | Z5: 0.046084307 | AA5: 0.010982407 | AF5: 0.0097420402 | AG5: 0.030133855 | AH5: 0.023504602 | AI5: 0.0073754022 | AJ5: 0.012999297 | AK5: 0.010979366 | AL5: 0.018274448 | AM5: 0.0078390783 | AO5: 0.0077229566 | AP5: 0.01838264 | AQ5: 0.011938214 | AR5: 0.0089617289 | AS5: 0.011078979 | AU5: 0.0097866128 | AV5: 0.0078981425 | AW5: 0.011856105 | AX5: 0.008805088 | AZ5: 0.0071765346 | BC5: 0.0082570834 | BD5: 0.01775268 | BE5: 0.0092435702 | BF5: 0.0071897776 | BG5: 0.010557251 | BH5: 0.0072401734 | BI5: 0.012538153 | BJ5: 0.008220299 | BK5: 0.02451292 | BL5: 0.009502322
A6: 2024-01-09 | B6: 0.0084977034 | C6: 0.013263576 | D6: 0.015904649 | E6: 0.016623207 | F6: 0.011473823 | H6: 0.013204008 | J6: 0.012250875 | K6: 0.0086747493 | L6: 0.020211592 | M6: 0.024713311 | N6: 0.045081127 | O6: 0.0076967165 | P6: 0.30470812 | Q6: 0.0093104649 | R6: 0.010881731 | T6: 0.0074560046 | U6: 0.026862881 | W6: 0.0099415091 | X6: 0.00724213 | Y6: 0.02997199 | Z6: 0.046530174 | AA6: 0.010376637 | AF6: 0.009641685 | AG6: 0.030116057 | AH6: 0.023344838 | AI6: 0.0072936168 | AJ6: 0.012860617 | AK6: 0.010949171 | AL6: 0.018292191 | AM6: 0.0078029754 | AO6: 0.0077304551 | AP6: 0.018206117 | AQ6: 0.0118621 | AR6: 0.009003902 | AS6: 0.011068244 | AU6: 0.009796115 | AV6: 0.0079794678 | AW6: 0.011879604 | AX6: 0.0087762913 | AZ6: 0.007291363 | BC6: 0.0085880495 | BD6: 0.017840432 | BE6: 0.0092873728 | BF6: 0.0071881807 | BG6: 0.010368651 | BH6: 0.0072315505 | BI6: 0.012479287 | BJ6: 0.0082704048 | BK6: 0.024322024 | BL6: 0.0096522515
A7: 2024-01-10 | B7: 0.008440596 | C7: 0.013311267 | D7: 0.01583842 | E7: 0.016529217 | F7: 0.011420383 | H7: 0.013175034 | J7: 0.012168915 | K7: 0.0081356824 | L7: 0.020284266 | M7: 0.024424473 | N7: 0.044795269 | O7: 0.0075876762 | P7: 0.30476004 | Q7: 0.0091990746 | R7: 0.011064869 | T7: 0.0075573932 | U7: 0.027209095 | W7: 0.009977255 | X7: 0.0071580462 | Y7: 0.030079758 | Z7: 0.046496197 | AA7: 0.010173361 | AF7: 0.0096763529 | AG7: 0.030224343 | AH7: 0.0234026 | AI7: 0.0072900864 | AJ7: 0.012856244 | AK7: 0.010865534 | AL7: 0.018311428 | AM7: 0.0078090964 | AO7: 0.00771826 | AP7: 0.018239068 | AQ7: 0.011838737 | AR7: 0.0090026846 | AS7: 0.010892352 | AU7: 0.0098706635 | AV7: 0.008008159 | AW7: 0.011886227 | AX7: 0.0088546979 | AZ7: 0.0077505729 | BC7: 0.0087629779 | BD7: 0.01790458 | BE7: 0.0093324177 | BF7: 0.0071365491 | BG7: 0.010434442 | BH7: 0.0070611901 | BI7: 0.012452863 | BJ7: 0.0082860501 | BK7: 0.024347915 | BL7: 0.0099976179
A8: 2024-01-11 | B8: 0.0084054378 | C8: 0.013219253 | D8: 0.015547126 | E8: 0.016205167 | F8: 0.011372812 | H8: 0.013094778 | J8: 0.012136153 | K8: 0.0082153708 | L8: 0.020199774 | M8: 0.024489903 | N8: 0.044831724 | O8: 0.0075424561 | P8: 0.30452996 | Q8: 0.0093771529 | R8: 0.01101878 | T8: 0.0074351408 | U8: 0.027841514 | W8: 0.0099080969 | X8: 0.0069188697 | Y8: 0.030079275 | Z8: 0.046102079 | AA8: 0.010199438 | AF8: 0.0097018972 | AG8: 0.030051418 | AH8: 0.023252983 | AI8: 0.0072597205 | AJ8: 0.012802693 | AK8: 0.010942769 | AL8: 0.018165643 | AM8: 0.0077765686 | AO8: 0.0077060228 | AP8: 0.018357353 | AQ8: 0.011855164 | AR8: 0.0090320894 | AS8: 0.010954377 | AU8: 0.0098295485 | AV8: 0.0078766506 | AW8: 0.01194454 | AX8: 0.0091070764 | AZ8: 0.0080201214 | BC8: 0.0091568236 | BD8: 0.017689052 | BE8: 0.0094327738 | BF8: 0.0070725317 | BG8: 0.010561323 | BH8: 0.0071256389 | BI8: 0.01235366 | BJ8: 0.0084339676 | BK8: 0.024123885 | BL8: 0.010743452
A9: 2024-01-12 | B9: 0.0084235962 | C9: 0.013283073 | D9: 0.015578128 | E9: 0.016343802 | F9: 0.01134275 | H9: 0.013103625 | J9: 0.012108476 | K9: 0.008107268 | L9: 0.020213422 | M9: 0.024548269 | N9: 0.044862013 | O9: 0.0076292945 | P9: 0.30369565 | Q9: 0.0092030366 | R9: 0.010727249 | T9: 0.0073823604 | U9: 0.028730959 | W9: 0.009790511 | X9: 0.0068636865 | Y9: 0.029974703 | Z9: 0.046434096 | AA9: 0.01072007 | AF9: 0.0096645225 | AG9: 0.030165843 | AH9: 0.023216521 | AI9: 0.0072646254 | AJ9: 0.012786123 | AK9: 0.010888874 | AL9: 0.018108358 | AM9: 0.0077162455 | AO9: 0.0076315266 | AP9: 0.018175367 | AQ9: 0.011797389 | AR9: 0.0089712422 | AS9: 0.011176715 | AU9: 0.0099929417 | AV9: 0.007808309 | AW9: 0.011964599 | AX9: 0.0092906386 | AZ9: 0.0078097997 | BC9: 0.0089357293 | BD9: 0.017771525 | BE9: 0.0094275366 | BF9: 0.0071202029 | BG9: 0.010483229 | BH9: 0.007099145 | BI9: 0.012314643 | BJ9: 0.0083975377 | BK9: 0.024232205 | BL9: 0.010722568
A10: 2024-01-15 | B10: 0.0083965401 | C10: 0.013206589 | D10: 0.015471775 | E10: 0.016237597 | F10: 0.011264444 | H10: 0.013100353 | J10: 0.01205165 | K10: 0.0081052435 | L10: 0.020490727 | M10: 0.024709376 | N10: 0.044627672 | O10: 0.0078453147 | P10: 0.30465961 | Q10: 0.0093089824 | R10: 0.010688702 | T10: 0.0075126067 | U10: 0.028164231 | W10: 0.0097742606 | X10: 0.007131265 | Y10: 0.030092081 | Z10: 0.046221971 | AA10: 0.010854357 | AF10: 0.009596231 | AG10: 0.03015831 | AH10: 0.023184644 | AI10: 0.007203523 | AJ10: 0.012808143 | AK10: 0.010906579 | AL10: 0.018034295 | AM10: 0.007692465 | AO10: 0.0076097001 | AP10: 0.018235608 | AQ10: 0.011750598 | AR10: 0.0089690019 | AS10: 0.011152435 | AU10: 0.010460585 | AV10: 0.0078309074 | AW10: 0.011877712 | AX10: 0.0092043036 | AZ10: 0.007592163 | BC10: 0.0088497837 | BD10: 0.017696583 | BE10: 0.0094251824 | BF10: 0.0070669663 | BG10: 0.010452208 | BH10: 0.0070738969 | BI10: 0.012311567 | BJ10: 0.0084656366 | BK10: 0.023980825 | BL10: 0.0104948
A11: 2024-01-16 | B11: 0.0083185293 | C11: 0.013196806 | D11: 0.015282921 | E11: 0.015987792 | F11: 0.010897971 | H11: 0.012965796 | J11: 0.011684861 | K11: 0.008174614 | L11: 0.020763125 | M11: 0.024529473 | N11: 0.04522094 | O11: 0.0077839914 | P11: 0.30554882 | Q11: 0.0093778921 | R11: 0.0106733 | T11: 0.0075790159 | U11: 0.028727636 | W11: 0.0095264946 | X11: 0.0070138321 | Y11: 0.030112547 | Z11: 0.045464868 | AA11: 0.010651691 | AF11: 0.0095457907 | AG11: 0.030130158 | AH11: 0.023255019 | AI11: 0.0071490937 | AJ11: 0.012774027 | AK11: 0.010865306 | AL11: 0.018133107 | AM11: 0.0076618619 | AO11: 0.0075897485 | AP11: 0.018346745 | AQ11: 0.011773522 | AR11: 0.0089864995 | AS11: 0.011235371 | AU11: 0.010579796 | AV11: 0.0080593826 | AW11: 0.011902017 | AX11: 0.0093266632 | AZ11: 0.0075838143 | BC11: 0.0088947215 | BD11: 0.017931836 | BE11: 0.0093740532 | BF11: 0.0071087701 | BG11: 0.010476036 | BH11: 0.0070569275 | BI11: 0.012235326 | BJ11: 0.0084074666 | BK11: 0.023243115 | BL11: 0.010890908
A12: 2024-01-17 | B12: 0.0082366867 | C12: 0.013182269 | D12: 0.015083392 | E12: 0.015729702 | F12: 0.010793219 | H12: 0.012909111 | J12: 0.011472107 | K12: 0.0083478019 | L12: 0.020096077 | M12: 0.023958934 | N12: 0.04510893 | O12: 0.0078051467 | P12: 0.30965263 | Q12: 0.0094135118 | R12: 0.010761265 | T12: 0.0074221587 | U12: 0.029127101 | W12: 0.0093830832 | X12: 0.0069322084 | Y12: 0.03033646 | Z12: 0.045173922 | AA12: 0.010705971 | AF12: 0.0094772587 | AG12: 0.030048196 | AH12: 0.023152503 | AI12: 0.0071414749 | AJ12: 0.01271654 | AK12: 0.010803846 | AL12: 0.017727185 | AM12: 0.0076169861 | AO12: 0.0075967616 | AP12: 0.018295523 | AQ12: 0.011731325 | AR12: 0.0090229063 | AS12: 0.010970163 | AU12: 0.010261645 | AV12: 0.0079774125 | AW12: 0.011942817 | AX12: 0.0093686732 | AZ12: 0.0074292251 | BC12: 0.0087412159 | BD12: 0.018069123 | BE12: 0.0094003106 | BF12: 0.007103928 | BG12: 0.010394649 | BH12: 0.0070431379 | BI12: 0.012208417 | BJ12: 0.0083042326 | BK12: 0.022948886 | BL12: 0.010873969
A13: 2024-01-18 | B13: 0.0081534355 | C13: 0.013259294 | D13: 0.014854571 | E13: 0.01564359 | F13: 0.010734132 | H13: 0.012838441 | J13: 0.011336167 | K13: 0.0082248731 | L13: 0.019780444 | M13: 0.023614643 | N13: 0.045453469 | O13: 0.0077346451 | P13: 0.31166777 | Q13: 0.0092700133 | R13: 0.010848627 | T13: 0.0074067766 | U13: 0.028080234 | W13: 0.0093317157 | X13: 0.0069349323 | Y13: 0.030170384 | Z13: 0.045846617 | AA13: 0.011031364 | AF13: 0.0094477637 | AG13: 0.029883698 | AH13: 0.023025755 | AI13: 0.007132602 | AJ13: 0.012621218 | AK13: 0.0107447 | AL13: 0.017866467 | AM13: 0.007575287 | AO13: 0.0076567213 | AP13: 0.0183935 | AQ13: 0.011711803 | AR13: 0.0090246903 | AS13: 0.010932015 | AU13: 0.010245411 | AV13: 0.0078586576 | AW13: 0.011889656 | AX13: 0.0092983501 | AZ13: 0.0075864616 | BC13: 0.0089981786 | BD13: 0.018257727 | BE13: 0.0094080187 | BF13: 0.0070562938 | BG13: 0.010250872 | BH13: 0.0070604255 | BI13: 0.012165721 | BJ13: 0.0083017111 | BK13: 0.0226044 | BL13: 0.010785754
... A60: 2024-04-08 | B60: 0.0068863562 | C60: 0.011784102 | D60: 0.012326436 | E60: 0.012586707 | F60: 0.00888298 | H60: 0.010846134 | J60: 0.0097915118 | K60: 0.0066444575 | L60: 0.017955729 | M60: 0.023862856 | N60: 0.060246661 | O60: 0.0071803351 | P60: 0.3462236 | Q60: 0.0071830698 | R60: 0.0087035955 | T60: 0.0079989683 | U60: 0.030969907 | W60: 0.009177025 | X60: 0.0058033573 | Y60: 0.026991521 | Z60: 0.049259165 | AA60: 0.0098300509 | AF60: 0.0086682793 | AG60: 0.027617056 | AH60: 0.021547496 | AI60: 0.0070919941 | AJ60: 0.011697524 | AK60: 0.010575273 | AL60: 0.015844598 | AM60: 0.0067406492 | AO60: 0.0072678125 | AP60: 0.017739507 | AQ60: 0.010283458 | AR60: 0.0077776767 | AS60: 0.0085951959 | AU60: 0.0098917665 | AV60: 0.0083478789 | AW60: 0.010650356 | AX60: 0.010528333 | AZ60: 0.00479146 | BC60: 0.0064374393 | BD60: 0.018433541 | BE60: 0.0080828218 | BF60: 0.0074011438 | BG60: 0.0085422949 | BH60: 0.0062446605 | BI60: 0.010600173 | BJ60: 0.0065186022 | BK60: 0.019048617 | BL60: 0.01189987
A61: 2024-04-09 | B61: 0.0072467011 | C61: 0.012526012 | D61: 0.013081707 | E61: 0.013417859 | F61: 0.0093926758 | G61: 0.0066499733 | H61: 0.011721574 | J61: 0.010207682 | K61: 0.0066083935 | L61: 0.018721869 | M61: 0.024537704 | N61: 0.060022219 | O61: 0.0073615461 | P61: 0.31038466 | Q61: 0.0074754551 | R61: 0.0090950253 | T61: 0.0083204093 | U61: 0.033010142 | W61: 0.0095489591 | Y61: 0.027766589 | Z61: 0.054301986 | AA61: 0.010207572 | AF61: 0.0090895577 | AG61: 0.029230429 | AH61: 0.02294932 | AI61: 0.0074554494 | AJ61: 0.012192557 | AK61: 0.011249541 | AL61: 0.016651098 | AM61: 0.0070005865 | AO61: 0.0076118572 | AP61: 0.018746236 | AQ61: 0.010698261 | AR61: 0.0080926945 | AS61: 0.0090817807 | AU61: 0.010564784 | AV61: 0.0084273264 | AW61: 0.011107988 | AX61: 0.010756844 | BC61: 0.0071433209 | BD61: 0.020182121 | BE61: 0.0083375833 | BF61: 0.0077811782 | BG61: 0.0089739567 | BH61: 0.0064837742 | BI61: 0.011053333 | BJ61: 0.0071336697 | BK61: 0.020096206 | BL61: 0.012739126 | BN61: 0.007562708
A62: 2024-04-10 | B62: 0.0073190395 | C62: 0.012537918 | D62: 0.013202968 | E62: 0.013379345 | F62: 0.0094475909 | G62: 0.0067511921 | H62: 0.011545131 | J62: 0.010214994 | K62: 0.00659149 | L62: 0.019050669 | M62: 0.024151382 | N62: 0.058825298 | O62: 0.0074501706 | P62: 0.30956699 | Q62: 0.0076695932 | R62: 0.0093300706 | T62: 0.0083832642 | U62: 0.032508377 | W62: 0.0093158169 | Y62: 0.027940234 | Z62: 0.056066872 | AA62: 0.010110991 | AF62: 0.0090904725 | AG62: 0.028961693 | AH62: 0.022675603 | AI62: 0.0073930921 | AJ62: 0.012152977 | AK62: 0.011129018 | AL62: 0.01673005 | AM62: 0.0070164125 | AO62: 0.0077000332 | AP62: 0.018613294 | AQ62: 0.010702986 | AR62: 0.0082001212 | AS62: 0.0091023117 | AU62: 0.01076633 | AV62: 0.0083590768 | AW62: 0.0111331 | AX62: 0.010738379 | BC62: 0.0071594697 | BD62: 0.020551909 | BE62: 0.008459853 | BF62: 0.0078375688 | BG62: 0.008994244 | BH62: 0.0065816562 | BI62: 0.01105722 | BJ62: 0.0071757488 | BK62: 0.020333986 | BL62: 0.012148874 | BN62: 0.0078751219
A63: 2024-04-11 | B63: 0.0072592796 | C63: 0.01255069 | D63: 0.0130145 | E63: 0.013140276 | F63: 0.0093560681 | G63: 0.0066430383 | H63: 0.01142146 | J63: 0.01013072 | K63: 0.0066300799 | L63: 0.018819153 | M63: 0.023549472 | N63: 0.057170117 | O63: 0.0073136485 | P63: 0.31178345 | Q63: 0.0076290188 | R63: 0.009736775 | T63: 0.0083330172 | U63: 0.032829981 | W63: 0.0093738758 | Y63: 0.028079683 | Z63: 0.056358813 | AA63: 0.010480627 | AF63: 0.0091193864 | AG63: 0.028656036 | AH63: 0.023141035 | AI63: 0.0074006232 | AJ63: 0.012210165 | AK63: 0.011140355 | AL63: 0.016602364 | AM63: 0.0069847557 | AO63: 0.0077966773 | AP63: 0.018690754 | AQ63: 0.010694409 | AR63: 0.0082530856 | AS63: 0.008862738 | AU63: 0.010937356 | AV63: 0.0084112868 | AW63: 0.011144441 | AX63: 0.010535188 | BC63: 0.0071548972 | BD63: 0.020637743 | BE63: 0.0084684707 | BF63: 0.007884392 | BG63: 0.0088520883 | BH63: 0.0065953031 | BI63: 0.011026237 | BJ63: 0.0070791444 | BK63: 0.020162155 | BL63: 0.012006329 | BN63: 0.0079488369
A64: 2024-04-12 | B64: 0.0072605455 | C64: 0.012696977 | D64: 0.012875939 | E64: 0.013270437 | F64: 0.0093818912 | G64: 0.0066565237 | H64: 0.011289959 | J64: 0.010131899 | K64: 0.006608266 | L64: 0.019011495 | M64: 0.02351443 | N64: 0.057727027 | O64: 0.007469132 | P64: 0.3130094 | Q64: 0.0074017985 | R64: 0.0095828864 | T64: 0.0084158184 | U64: 0.030426677 | W64: 0.0092504454 | Y64: 0.028035627 | Z64: 0.055773445 | AA64: 0.010637971 | AF64: 0.0090985113 | AG64: 0.028586078 | AH64: 0.022984247 | AI64: 0.00734149 | AJ64: 0.012220506 | AK64: 0.011137986 | AL64: 0.016625168 | AM64: 0.0069903129 | AO64: 0.007810725 | AP64: 0.018692378 | AQ64: 0.010723502 | AR64: 0.0082309683 | AS64: 0.0090541909 | AU64: 0.011275678 | AV64: 0.0085309679 | AW64: 0.011269537 | AX64: 0.010559373 | BC64: 0.0069259436 | BD64: 0.020965488 | BE64: 0.0085017184 | BF64: 0.0076845874 | BG64: 0.0088578621 | BH64: 0.006637425 | BI64: 0.0110754 | BJ64: 0.0071243564 | BK64: 0.020069467 | BL64: 0.012498769 | BN64: 0.008098772
A65: 2024-04-15 | B65: 0.0074026341 | C65: 0.012868653 | D65: 0.013048301 | E65: 0.013420478 | F65: 0.0094694895 | G65: 0.0066084679 | H65: 0.011319209 | J65: 0.010233931 | K65: 0.0066412386 | L65: 0.018890957 | M65: 0.02318593 | N65: 0.05683216 | O65: 0.0073837463 | P65: 0.31299524 | Q65: 0.0070998358 | R65: 0.0096593353 | T65: 0.008420649 | U65: 0.029738862 | W65: 0.0092885345 | Y65: 0.028565097 | Z65: 0.053243556 | AA65: 0.010887613 | AF65: 0.0092134824 | AG65: 0.028839213 | AH65: 0.023277835 | AI65: 0.0073694723 | AJ65: 0.012379006 | AK65: 0.011396562 | AL65: 0.016808577 | AM65: 0.0070742503 | AO65: 0.0079085163 | AP65: 0.019089313 | AQ65: 0.010822979 | AR65: 0.0083683233 | AS65: 0.0089735253 | AU65: 0.011225074 | AV65: 0.0081443807 | AW65: 0.011382083 | AX65: 0.010453665 | BC65: 0.0066773043 | BD65: 0.021210384 | BE65: 0.0087019184 | BF65: 0.0078303794 | BG65: 0.0089120621 | BH65: 0.0067217596 | BI65: 0.011261359 | BJ65: 0.0072300992 | BK65: 0.020676369 | BL65: 0.012763393 | BN65: 0.0080847901
A66: 2024-04-16 | B66: 0.0076358426 | C66: 0.012853585 | D66: 0.013109433 | E66: 0.013390451 | F66: 0.0095429558 | G66: 0.0065238248 | H66: 0.011497584 | J66: 0.0101592 | K66: 0.0063807552 | L66: 0.018861328 | M66: 0.022681496 | N66: 0.056440479 | O66: 0.0073784716 | P66: 0.31467279 | Q66: 0.0070553134 | R66: 0.0095946948 | T66: 0.0085048092 | U66: 0.029233759 | W66: 0.0093093319 | Y66: 0.029024502 | Z66: 0.052038744 | AA66: 0.01072426 | AF66: 0.009247395 | AG66: 0.028908073 | AH66: 0.023399259 | AI66: 0.0073561384 | AJ66: 0.01237669 | AK66: 0.011489199 | AL66: 0.016980673 | AM66: 0.0070912324 | AO66: 0.0079273444 | AP66: 0.019015615 | AQ66: 0.010945409 | AR66: 0.008433559 | AS66: 0.008946243 | AU66: 0.011244172 | AV66: 0.0081226686 | AW66: 0.011479391 | AX66: 0.010255003 | BC66: 0.0070533637 | BD66: 0.020856924 | BE66: 0.0088287958 | BF66: 0.007782951 | BG66: 0.0090055718 | BH66: 0.0067225777 | BI66: 0.011402858 | BJ66: 0.0072984696 | BK66: 0.020539806 | BL66: 0.012501208 | BN66: 0.0081758012
A67: 2024-04-17 | B67: 0.0075907537 | C67: 0.012852831 | D67: 0.0129141 | E67: 0.013110654 | F67: 0.009376017 | G67: 0.0066544604 | H67: 0.011453366 | J67: 0.0099227286 | K67: 0.0063703738 | L67: 0.018709491 | M67: 0.022983068 | N67: 0.057938688 | O67: 0.0073896639 | P67: 0.31721117 | Q67: 0.0068284309 | R67: 0.0095464494 | T67: 0.0086925516 | U67: 0.029461941 | W67: 0.0093488676 | Y67: 0.028446041 | Z67: 0.051170905 | AA67: 0.01059563 | AF67: 0.0091568729 | AG67: 0.028691758 | AH67: 0.023142758 | AI67: 0.0073227587 | AJ67: 0.012321231 | AK67: 0.011370345 | AL67: 0.016734094 | AM67: 0.0070665761 | AO67: 0.0079428346 | AP67: 0.019121402 | AQ67: 0.010874766 | AR67: 0.0084095562 | AS67: 0.0087396251 | AU67: 0.011459932 | AV67: 0.0081159235 | AW67: 0.011341704 | AX67: 0.01017644 | BC67: 0.0071411357 | BD67: 0.021010814 | BE67: 0.0086369607 | BF67: 0.0077702037 | BG67: 0.0089237255 | BH67: 0.0066851682 | BI67: 0.011266088 | BJ67: 0.0073322349 | BK67: 0.020065108 | BL67: 0.012806734 | BN67: 0.0078050719
A68: 2024-04-18 | B68: 0.007576161 | C68: 0.013046331 | D68: 0.01292651 | E68: 0.013255484 | F68: 0.0093436833 | G68: 0.0066017745 | H68: 0.011577258 | J68: 0.0098885096 | K68: 0.0065263979 | L68: 0.018607903 | M68: 0.023551671 | N68: 0.058330067 | O68: 0.0073641803 | P68: 0.31611725 | Q68: 0.0068215613 | R68: 0.0094802252 | T68: 0.008723365 | U68: 0.028898881 | W68: 0.0093417397 | Y68: 0.028462713 | Z68: 0.05099444 | AA68: 0.010404265 | AF68: 0.0092065893 | AG68: 0.02872278 | AH68: 0.023327764 | AI68: 0.0073795003 | AJ68: 0.012510415 | AK68: 0.011557756 | AL68: 0.016761905 | AM68: 0.0070622699 | AO68: 0.0079521739 | AP68: 0.019176448 | AQ68: 0.010837264 | AR68: 0.0083498011 | AS68: 0.0087094861 | AU68: 0.01131007 | AV68: 0.0080653434 | AW68: 0.011468806 | AX68: 0.010451344 | BC68: 0.0074477949 | BD68: 0.020267256 | BE68: 0.0086071757 | BF68: 0.007759473 | BG68: 0.0089711888 | BH68: 0.006611861 | BI68: 0.011292765 | BJ68: 0.0073472451 | BK68: 0.019995912 | BL68: 0.013349968 | BN68: 0.0076592756
A69: 2024-04-19 | B69: 0.0077156128 | C69: 0.013435684 | D69: 0.013254877 | E69: 0.013597 | F69: 0.009506127 | G69: 0.0065299397 | H69: 0.011878234 | J69: 0.010205909 | K69: 0.0065929646 | L69: 0.018940621 | M69: 0.023676995 | N69: 0.058652401 | O69: 0.007599168 | P69: 0.3068827 | Q69: 0.0069602342 | R69: 0.0095540012 | T69: 0.0087303213 | U69: 0.028994086 | W69: 0.0095388647 | Y69: 0.029381822 | Z69: 0.050188218 | AA69: 0.011117579 | AF69: 0.0093907989 | AG69: 0.029305242 | AH69: 0.023775768 | AI69: 0.0075090694 | AJ69: 0.012802402 | AK69: 0.011752826 | AL69: 0.017221354 | AM69: 0.0072451958 | AO69: 0.0081036902 | AP69: 0.019515945 | AQ69: 0.011173355 | AR69: 0.0086414986 | AS69: 0.0087342318 | AU69: 0.011253471 | AV69: 0.0079937869 | AW69: 0.01176243 | AX69: 0.010600027 | BC69: 0.0073038871 | BD69: 0.02039341 | BE69: 0.0089350706 | BF69: 0.0079246928 | BG69: 0.0091190549 | BH69: 0.0067239674 | BI69: 0.011638546 | BJ69: 0.0072687468 | BK69: 0.020513423 | BL69: 0.012865013 | BN69: 0.0075997379
A70: 2024-04-22 | B70: 0.0078707948 | C70: 0.013967019 | D70: 0.013786896 | E70: 0.01418455 | F70: 0.010009318 | G70: 0.0066936193 | H70: 0.01201574 | J70: 0.010389603 | K70: 0.0066498716 | L70: 0.018888702 | M70: 0.023827806 | N70: 0.058730857 | O70: 0.0077516845 | P70: 0.30401541 | Q70: 0.0066827678 | R70: 0.0095667811 | T70: 0.0079818256 | U70: 0.027650352 | W70: 0.0096432153 | Y70: 0.030019115 | Z70: 0.048888892 | AA70: 0.011229255 | AF70: 0.0096363266 | AG70: 0.029886185 | AH70: 0.024284224 | AI70: 0.0076900028 | AJ70: 0.01306095 | AK70: 0.011768547 | AL70: 0.017600863 | AM70: 0.007380332 | AO70: 0.0083059105 | AP70: 0.019762687 | AQ70: 0.011377221 | AR70: 0.0088934205 | AS70: 0.0087046608 | AU70: 0.011000226 | AV70: 0.0078867668 | AW70: 0.012066844 | AX70: 0.010014273 | BC70: 0.0070707209 | BD70: 0.020210888 | BE70: 0.0090362697 | BF70: 0.0079101816 | BG70: 0.0093758401 | BH70: 0.0068152534 | BI70: 0.011881734 | BJ70: 0.0070405199 | BK70: 0.02154864 | BL70: 0.012019697 | BN70: 0.0073267444
