Workbook

Sheet 每日指數值
A1: date | B1: price_index | C1: total_return_index | D1: price_daily_return | E1: tr_daily_return
A2: 2024-01-03 | B2: 100 | C2: 100
A3: 2024-01-04 | B3: 100.0275 | C3: 100.24659 | D3: 0.00027504329 | E3: 0.0024659266
A4: 2024-01-05 | B4: 99.387924 | C4: 99.605612 | D4: -0.0063940441 | E4: -0.0063940441
A5: 2024-01-08 | B5: 100.19869 | C5: 100.41815 | D5: 0.008157569 | E5: 0.008157569
A6: 2024-01-09 | B6: 100.66359 | C6: 100.88407 | D6: 0.0046398346 | E6: 0.0046398346
A7: 2024-01-10 | B7: 100.26211 | C7: 100.48171 | D7: -0.0039883706 | E7: -0.0039883706
A8: 2024-01-11 | B8: 100.55541 | C8: 100.77565 | D8: 0.0029253062 | E8: 0.0029253062
A9: 2024-01-12 | B9: 100.31816 | C9: 100.53789 | D9: -0.0023593448 | E9: -0.0023593448
A10: 2024-01-15 | B10: 100.53411 | C10: 100.75431 | D10: 0.002152634 | E10: 0.002152634
A11: 2024-01-16 | B11: 99.431372 | C11: 99.649154 | D11: -0.010968799 | E11: -0.010968799
A12: 2024-01-17 | B12: 99.328749 | C12: 99.546307 | D12: -0.0010320983 | E12: -0.0010320983
A13: 2024-01-18 | B13: 100.59853 | C13: 100.81887 | D13: 0.012783619 | E13: 0.012783619
A14: 2024-01-19 | B14: 106.34298 | C14: 106.5759 | D14: 0.05710274 | E14: 0.05710274
... A479: 2025-12-22 | B479: 240.42641 | C479: 250.01999 | D479: 0.024743515 | E479: 0.024743515

Sheet 投資後權重
A1: date | B1: 2308 | C1: 2317 | D1: 2330 | E1: 2454 | F1: 權重驗證 | G1: 2308 | H1: 2317 | I1: 2330 | J1: 2454 | K1: 2308 | L1: 2317 | M1: 2330 | N1: 2454 | O1: 現金股利殖利率
A2: 2024-01-03 | B2: 0 | C2: 0.080652758 | D2: 0.83447278 | E2: 0.084874462 | F2: =SUM(B2:E2) -> 1 | K2: =IFERROR(G3/每日收盤價!B2,0) -> 0 | L2: =IFERROR(H3/每日收盤價!C2,0) -> 0 | M2: =IFERROR(I3/每日收盤價!D2,0) -> 0 | N2: =IFERROR(J3/每日收盤價!E2,0) -> 0.025813221 | O2: =SUM(K2:N2) -> 0.025813221
A3: 2024-01-04 | B3: =B2*(1+$O2)*(1+每日報酬率!B3) -> 0 | C3: =C2*(1+每日報酬率!C3)*(1+$E2*$O2) -> 0.080442715 | D3: =D2*(1+每日報酬率!D3)*(1+$E2*$O2) -> 0.83919479 | E3: =E2*(1+每日報酬率!E3-O2)*(1+$E2*$O2) -> 0.080633344 | F3: =SUM(B3:E3) -> 1.0002708 | J3: 24.6 | K3: =IFERROR(G4/每日收盤價!B3,0) -> 0 | L3: =IFERROR(H4/每日收盤價!C3,0) -> 0 | M3: =IFERROR(I4/每日收盤價!D3,0) -> 0 | N3: =IFERROR(J4/每日收盤價!E3,0) -> 0 | O3: =SUM(K3:N3) -> 0
A4: 2024-01-05 | B4: =B3*(1+$CD$2)*(1+每日報酬率!B4) -> 0 | C4: =C3*(1+$CD$2)*(1+每日報酬率!C4) -> 0.080442715 | D4: =D3*(1+$CD$2)*(1+每日報酬率!D4) -> 0.83340724 | E4: =E3*(1+$CD$2)*(1+每日報酬率!E4) -> 0.080025118 | F4: =SUM(B4:E4) -> 0.99387507 | K4: =IFERROR(G5/每日收盤價!B4,0) -> 0 | L4: =IFERROR(H5/每日收盤價!C4,0) -> 0 | M4: =IFERROR(I5/每日收盤價!D4,0) -> 0 | N4: =IFERROR(J5/每日收盤價!E4,0) -> 0 | O4: =SUM(K4:N4) -> 0
A5: 2024-01-08 | B5: =B4*(1+$CD$2)*(1+每日報酬率!B5) -> 0 | C5: =C4*(1+$CD$2)*(1+每日報酬率!C5) -> 0.078508996 | D5: =D4*(1+$CD$2)*(1+每日報酬率!D5) -> 0.84353545 | E5: =E4*(1+$CD$2)*(1+每日報酬率!E5) -> 0.079938229 | F5: =SUM(B5:E5) -> 1.0019827 | K5: =IFERROR(G6/每日收盤價!B5,0) -> 0 | L5: =IFERROR(H6/每日收盤價!C5,0) -> 0 | M5: =IFERROR(I6/每日收盤價!D5,0) -> 0 | N5: =IFERROR(J6/每日收盤價!E5,0) -> 0 | O5: =SUM(K5:N5) -> 0
A6: 2024-01-09 | B6: =B5*(1+$CD$2)*(1+每日報酬率!B6) -> 0 | C6: =C5*(1+$CD$2)*(1+每日報酬率!C6) -> 0.078122252 | D6: =D5*(1+$CD$2)*(1+每日報酬率!D6) -> 0.84787611 | E6: =E5*(1+$CD$2)*(1+每日報酬率!E6) -> 0.080633344 | F6: =SUM(B6:E6) -> 1.0066317 | K6: =IFERROR(G7/每日收盤價!B6,0) -> 0 | L6: =IFERROR(H7/每日收盤價!C6,0) -> 0 | M6: =IFERROR(I7/每日收盤價!D6,0) -> 0 | N6: =IFERROR(J7/每日收盤價!E6,0) -> 0 | O6: =SUM(K6:N6) -> 0
A7: 2024-01-10 | B7: =B6*(1+$CD$2)*(1+每日報酬率!B7) -> 0 | C7: =C6*(1+$CD$2)*(1+每日報酬率!C7) -> 0.077348764 | D7: =D6*(1+$CD$2)*(1+每日報酬率!D7) -> 0.84498234 | E7: =E6*(1+$CD$2)*(1+每日報酬率!E7) -> 0.080285786 | F7: =SUM(B7:E7) -> 1.0026169 | K7: =IFERROR(G8/每日收盤價!B7,0) -> 0 | L7: =IFERROR(H8/每日收盤價!C7,0) -> 0 | M7: =IFERROR(I8/每日收盤價!D7,0) -> 0 | N7: =IFERROR(J8/每日收盤價!E7,0) -> 0 | O7: =SUM(K7:N7) -> 0
A8: 2024-01-11 | B8: =B7*(1+$CD$2)*(1+每日報酬率!B8) -> 0 | C8: =C7*(1+$CD$2)*(1+每日報酬率!C8) -> 0.077735508 | D8: =D7*(1+$CD$2)*(1+每日報酬率!D8) -> 0.84787611 | E8: =E7*(1+$CD$2)*(1+每日報酬率!E8) -> 0.079938229 | F8: =SUM(B8:E8) -> 1.0055498 | K8: =IFERROR(G9/每日收盤價!B8,0) -> 0 | L8: =IFERROR(H9/每日收盤價!C8,0) -> 0 | M8: =IFERROR(I9/每日收盤價!D8,0) -> 0 | N8: =IFERROR(J9/每日收盤價!E8,0) -> 0 | O8: =SUM(K8:N8) -> 0
A9: 2024-01-12 | B9: =B8*(1+$CD$2)*(1+每日報酬率!B9) -> 0 | C9: =C8*(1+$CD$2)*(1+每日報酬率!C9) -> 0.077735508 | D9: =D8*(1+$CD$2)*(1+每日報酬率!D9) -> 0.84498234 | E9: =E8*(1+$CD$2)*(1+每日報酬率!E9) -> 0.080459565 | F9: =SUM(B9:E9) -> 1.0031774 | K9: =IFERROR(G10/每日收盤價!B9,0) -> 0 | L9: =IFERROR(H10/每日收盤價!C9,0) -> 0 | M9: =IFERROR(I10/每日收盤價!D9,0) -> 0 | N9: =IFERROR(J10/每日收盤價!E9,0) -> 0 | O9: =SUM(K9:N9) -> 0
A10: 2024-01-15 | B10: =B9*(1+$CD$2)*(1+每日報酬率!B10) -> 0 | C10: =C9*(1+$CD$2)*(1+每日報酬率!C10) -> 0.077348764 | D10: =D9*(1+$CD$2)*(1+每日報酬率!D10) -> 0.84787611 | E10: =E9*(1+$CD$2)*(1+每日報酬率!E10) -> 0.080112007 | F10: =SUM(B10:E10) -> 1.0053369 | K10: =IFERROR(G11/每日收盤價!B10,0) -> 0 | L10: =IFERROR(H11/每日收盤價!C10,0) -> 0 | M10: =IFERROR(I11/每日收盤價!D10,0) -> 0 | N10: =IFERROR(J11/每日收盤價!E10,0) -> 0 | O10: =SUM(K10:N10) -> 0
A11: 2024-01-16 | B11: =B10*(1+$CD$2)*(1+每日報酬率!B11) -> 0 | C11: =C10*(1+$CD$2)*(1+每日報酬率!C11) -> 0.077348764 | D11: =D10*(1+$CD$2)*(1+每日報酬率!D11) -> 0.83919479 | E11: =E10*(1+$CD$2)*(1+每日報酬率!E11) -> 0.077765994 | F11: =SUM(B11:E11) -> 0.99430955 | K11: =IFERROR(G12/每日收盤價!B11,0) -> 0 | L11: =IFERROR(H12/每日收盤價!C11,0) -> 0 | M11: =IFERROR(I12/每日收盤價!D11,0) -> 0 | N11: =IFERROR(J12/每日收盤價!E11,0) -> 0 | O11: =SUM(K11:N11) -> 0
A12: 2024-01-17 | B12: =B11*(1+$CD$2)*(1+每日報酬率!B12) -> 0 | C12: =C11*(1+$CD$2)*(1+每日報酬率!C12) -> 0.076265882 | D12: =D11*(1+$CD$2)*(1+每日報酬率!D12) -> 0.84064167 | E12: =E11*(1+$CD$2)*(1+每日報酬率!E12) -> 0.076375764 | F12: =SUM(B12:E12) -> 0.99328332 | K12: =IFERROR(G13/每日收盤價!B12,0) -> 0 | L12: =IFERROR(H13/每日收盤價!C12,0) -> 0 | M12: =IFERROR(I13/每日收盤價!D12,0) -> 0 | N12: =IFERROR(J13/每日收盤價!E12,0) -> 0 | O12: =SUM(K12:N12) -> 0
A13: 2024-01-18 | B13: =B12*(1+$CD$2)*(1+每日報酬率!B13) -> 0 | C13: =C12*(1+$CD$2)*(1+每日報酬率!C13) -> 0.077271416 | D13: =D12*(1+$CD$2)*(1+每日報酬率!D13) -> 0.85076989 | E13: =E12*(1+$CD$2)*(1+每日報酬率!E13) -> 0.077939773 | F13: =SUM(B13:E13) -> 1.0059811 | K13: =IFERROR(G14/每日收盤價!B13,0) -> 0 | L13: =IFERROR(H14/每日收盤價!C13,0) -> 0 | M13: =IFERROR(I14/每日收盤價!D13,0) -> 0 | N13: =IFERROR(J14/每日收盤價!E13,0) -> 0 | O13: =SUM(K13:N13) -> 0
A14: 2024-01-19 | B14: =B13*(1+$CD$2)*(1+每日報酬率!B14) -> 0 | C14: =C13*(1+$CD$2)*(1+每日報酬率!C14) -> 0.077735508 | D14: =D13*(1+$CD$2)*(1+每日報酬率!D14) -> 0.90575162 | E14: =E13*(1+$CD$2)*(1+每日報酬率!E14) -> 0.079938229 | F14: =SUM(B14:E14) -> 1.0634254 | K14: =IFERROR(G15/每日收盤價!B14,0) -> 0 | L14: =IFERROR(H15/每日收盤價!C14,0) -> 0 | M14: =IFERROR(I15/每日收盤價!D14,0) -> 0 | N14: =IFERROR(J15/每日收盤價!E14,0) -> 0 | O14: =SUM(K14:N14) -> 0
A15: 2024-01-22 | B15: =B14*(1+$CD$2)*(1+每日報酬率!B15) -> 0 | C15: =C14*(1+$CD$2)*(1+每日報酬率!C15) -> 0.077271416 | D15: =D14*(1+$CD$2)*(1+每日報酬率!D15) -> 0.90575162 | E15: =E14*(1+$CD$2)*(1+每日報酬率!E15) -> 0.080112007 | F15: =SUM(B15:E15) -> 1.063135 | K15: =IFERROR(G16/每日收盤價!B15,0) -> 0 | L15: =IFERROR(H16/每日收盤價!C15,0) -> 0 | M15: =IFERROR(I16/每日收盤價!D15,0) -> 0 | N15: =IFERROR(J16/每日收盤價!E15,0) -> 0 | O15: =SUM(K15:N15) -> 0
... A46: 2024-03-15 | B46: =B45*(1+$CD$2)*(1+每日報酬率!B46) -> 0 | C46: =C45*(1+$CD$2)*(1+每日報酬率!C46) -> 0.10210037 | D46: =D45*(1+$CD$2)*(1+每日報酬率!D46) -> 1.0895063 | E46: =E45*(1+$CD$2)*(1+每日報酬率!E46) -> 0.098619445 | F46: =SUM(B46:E46) -> 1.2902262 | K46: =IFERROR(G47/每日收盤價!B46,0) -> 0 | L46: =IFERROR(H47/每日收盤價!C46,0) -> 0 | M46: =IFERROR(I47/每日收盤價!D46,0) -> 0.0046477951 | N46: =IFERROR(J47/每日收盤價!E46,0) -> 0 | O46: =SUM(K46:N46) -> 0.0046477951
A47: 2024-03-18 | B47: =B46*(1+$CD$2)*(1+每日報酬率!B47) -> 0 | C47: =C46*(1+$CD$2)*(1+每日報酬率!C47) -> 0.10519432 | D47: =D46*(1+$CD$2)*(1+每日報酬率!D47) -> 1.1054221 | E47: =E46*(1+$CD$2)*(1+每日報酬率!E47) -> 0.10166057 | F47: =SUM(B47:E47) -> 1.312277 | I47: 3.4997897 | K47: =IFERROR(G48/每日收盤價!B47,0) -> 0 | L47: =IFERROR(H48/每日收盤價!C47,0) -> 0 | M47: =IFERROR(I48/每日收盤價!D47,0) -> 0 | N47: =IFERROR(J48/每日收盤價!E47,0) -> 0 | O47: =SUM(K47:N47) -> 0
A48: 2024-03-19 | B48: =B47*(1+$CD$2)*(1+每日報酬率!B48) -> 0 | C48: =C47*(1+$CD$2)*(1+每日報酬率!C48) -> 0.10519432 | D48: =D47*(1+$CD$2)*(1+每日報酬率!D48) -> 1.1025283 | E48: =E47*(1+$CD$2)*(1+每日報酬率!E48) -> 0.099922786 | F48: =SUM(B48:E48) -> 1.3076454 | K48: =IFERROR(G49/每日收盤價!B48,0) -> 0 | L48: =IFERROR(H49/每日收盤價!C48,0) -> 0 | M48: =IFERROR(I49/每日收盤價!D48,0) -> 0 | N48: =IFERROR(J49/每日收盤價!E48,0) -> 0 | O48: =SUM(K48:N48) -> 0
A49: 2024-03-20 | B49: =B48*(1+$CD$2)*(1+每日報酬率!B49) -> 0 | C49: =C48*(1+$CD$2)*(1+每日報酬率!C49) -> 0.10674129 | D49: =D48*(1+$CD$2)*(1+每日報酬率!D49) -> 1.0967408 | E49: =E48*(1+$CD$2)*(1+每日報酬率!E49) -> 0.098184998 | F49: =SUM(B49:E49) -> 1.3016671 | K49: =IFERROR(G50/每日收盤價!B49,0) -> 0 | L49: =IFERROR(H50/每日收盤價!C49,0) -> 0 | M49: =IFERROR(I50/每日收盤價!D49,0) -> 0 | N49: =IFERROR(J50/每日收盤價!E49,0) -> 0 | O49: =SUM(K49:N49) -> 0
A50: 2024-03-21 | B50: =B49*(1+$CD$2)*(1+每日報酬率!B50) -> 0 | C50: =C49*(1+$CD$2)*(1+每日報酬率!C50) -> 0.11022199 | D50: =D49*(1+$CD$2)*(1+每日報酬率!D50) -> 1.1343599 | E50: =E49*(1+$CD$2)*(1+每日報酬率!E50) -> 0.099053892 | F50: =SUM(B50:E50) -> 1.3436357 | K50: =IFERROR(G51/每日收盤價!B50,0) -> 0 | L50: =IFERROR(H51/每日收盤價!C50,0) -> 0 | M50: =IFERROR(I51/每日收盤價!D50,0) -> 0 | N50: =IFERROR(J51/每日收盤價!E50,0) -> 0 | O50: =SUM(K50:N50) -> 0
A51: 2024-03-22 | B51: =B50*(1+$CD$2)*(1+每日報酬率!B51) -> 0 | C51: =C50*(1+$CD$2)*(1+每日報酬率!C51) -> 0.11254245 | D51: =D50*(1+$CD$2)*(1+每日報酬率!D51) -> 1.1358067 | E51: =E50*(1+$CD$2)*(1+每日報酬率!E51) -> 0.097750551 | F51: =SUM(B51:E51) -> 1.3460997 | K51: =IFERROR(G52/每日收盤價!B51,0) -> 0 | L51: =IFERROR(H52/每日收盤價!C51,0) -> 0 | M51: =IFERROR(I52/每日收盤價!D51,0) -> 0 | N51: =IFERROR(J52/每日收盤價!E51,0) -> 0 | O51: =SUM(K51:N51) -> 0
A52: 2024-03-25 | B52: =B51*(1+$CD$2)*(1+每日報酬率!B52) -> 0 | C52: =C51*(1+$CD$2)*(1+每日報酬率!C52) -> 0.11254245 | D52: =D51*(1+$CD$2)*(1+每日報酬率!D52) -> 1.1285723 | E52: =E51*(1+$CD$2)*(1+每日報酬率!E52) -> 0.097316104 | F52: =SUM(B52:E52) -> 1.3384309 | K52: =IFERROR(G53/每日收盤價!B52,0) -> 0 | L52: =IFERROR(H53/每日收盤價!C52,0) -> 0 | M52: =IFERROR(I53/每日收盤價!D52,0) -> 0 | N52: =IFERROR(J53/每日收盤價!E52,0) -> 0 | O52: =SUM(K52:N52) -> 0
A53: 2024-03-26 | B53: =B52*(1+$CD$2)*(1+每日報酬率!B53) -> 0 | C53: =C52*(1+$CD$2)*(1+每日報酬率!C53) -> 0.10983525 | D53: =D52*(1+$CD$2)*(1+每日報酬率!D53) -> 1.1314661 | E53: =E52*(1+$CD$2)*(1+每日報酬率!E53) -> 0.098184998 | F53: =SUM(B53:E53) -> 1.3394863 | K53: =IFERROR(G54/每日收盤價!B53,0) -> 0 | L53: =IFERROR(H54/每日收盤價!C53,0) -> 0 | M53: =IFERROR(I54/每日收盤價!D53,0) -> 0 | N53: =IFERROR(J54/每日收盤價!E53,0) -> 0 | O53: =SUM(K53:N53) -> 0
A54: 2024-03-27 | B54: =B53*(1+$CD$2)*(1+每日報酬率!B54) -> 0 | C54: =C53*(1+$CD$2)*(1+每日報酬率!C54) -> 0.11486292 | D54: =D53*(1+$CD$2)*(1+每日報酬率!D54) -> 1.1271254 | E54: =E53*(1+$CD$2)*(1+每日報酬率!E54) -> 0.10122613 | F54: =SUM(B54:E54) -> 1.3432145 | K54: =IFERROR(G55/每日收盤價!B54,0) -> 0 | L54: =IFERROR(H55/每日收盤價!C54,0) -> 0 | M54: =IFERROR(I55/每日收盤價!D54,0) -> 0 | N54: =IFERROR(J55/每日收盤價!E54,0) -> 0 | O54: =SUM(K54:N54) -> 0
A55: 2024-03-28 | B55: =B54*(1+$CD$2)*(1+每日報酬率!B55) -> 0 | C55: =C54*(1+$CD$2)*(1+每日報酬率!C55) -> 0.12027733 | D55: =D54*(1+$CD$2)*(1+每日報酬率!D55) -> 1.1126565 | E55: =E54*(1+$CD$2)*(1+每日報酬率!E55) -> 0.10079168 | F55: =SUM(B55:E55) -> 1.3337255 | K55: =IFERROR(G56/每日收盤價!B55,0) -> 0 | L55: =IFERROR(H56/每日收盤價!C55,0) -> 0 | M55: =IFERROR(I56/每日收盤價!D55,0) -> 0 | N55: =IFERROR(J56/每日收盤價!E55,0) -> 0 | O55: =SUM(K55:N55) -> 0
A56: 2024-03-29 | B56: =B55*(1+$CD$2)*(1+每日報酬率!B56) -> 0 | C56: =C55*(1+$CD$2)*(1+每日報酬率!C56) -> 0.11602315 | D56: =D55*(1+$CD$2)*(1+每日報酬率!D56) -> 1.1271254 | E56: =E55*(1+$CD$2)*(1+每日報酬率!E56) -> 0.10383281 | F56: =SUM(B56:E56) -> 1.3469814 | K56: =IFERROR(G57/每日收盤價!B56,0) -> 0 | L56: =IFERROR(H57/每日收盤價!C56,0) -> 0 | M56: =IFERROR(I57/每日收盤價!D56,0) -> 0 | N56: =IFERROR(J57/每日收盤價!E56,0) -> 0 | O56: =SUM(K56:N56) -> 0
A57: 2024-04-01 | B57: =B56*(1+$CD$2)*(1+每日報酬率!B57) -> 0 | C57: =C56*(1+$CD$2)*(1+每日報酬率!C57) -> 0.11640989 | D57: =D56*(1+$CD$2)*(1+每日報酬率!D57) -> 1.1141034 | E57: =E56*(1+$CD$2)*(1+每日報酬率!E57) -> 0.10079168 | F57: =SUM(B57:E57) -> 1.331305 | K57: =IFERROR(G58/每日收盤價!B57,0) -> 0 | L57: =IFERROR(H58/每日收盤價!C57,0) -> 0 | M57: =IFERROR(I58/每日收盤價!D57,0) -> 0 | N57: =IFERROR(J58/每日收盤價!E57,0) -> 0 | O57: =SUM(K57:N57) -> 0
A58: 2024-04-02 | B58: =B57*(1+$CD$2)*(1+每日報酬率!B58) -> 0 | C58: =C57*(1+$CD$2)*(1+每日報酬率!C58) -> 0.12298454 | D58: =D57*(1+$CD$2)*(1+每日報酬率!D58) -> 1.1430412 | E58: =E57*(1+$CD$2)*(1+每日報酬率!E58) -> 0.10122613 | F58: =SUM(B58:E58) -> 1.3672518 | K58: =IFERROR(G59/每日收盤價!B58,0) -> 0 | L58: =IFERROR(H59/每日收盤價!C58,0) -> 0 | M58: =IFERROR(I59/每日收盤價!D58,0) -> 0 | N58: =IFERROR(J59/每日收盤價!E58,0) -> 0 | O58: =SUM(K58:N58) -> 0
A59: 2024-04-03 | B59: =B58*(1+$CD$2)*(1+每日報酬率!B59) -> 0 | C59: =C58*(1+$CD$2)*(1+每日報酬率!C59) -> 0.12298454 | D59: =D58*(1+$CD$2)*(1+每日報酬率!D59) -> 1.1285723 | E59: =E58*(1+$CD$2)*(1+每日報酬率!E59) -> 0.10079168 | F59: =SUM(B59:E59) -> 1.3523485 | K59: =IFERROR(G60/每日收盤價!B59,0) -> 0 | L59: =IFERROR(H60/每日收盤價!C59,0) -> 0 | M59: =IFERROR(I60/每日收盤價!D59,0) -> 0 | N59: =IFERROR(J60/每日收盤價!E59,0) -> 0 | O59: =SUM(K59:N59) -> 0
... A105: 2024-06-12 | B105: =B104*(1+$CD$2)*(1+每日報酬率!B105) -> 0 | C105: =C104*(1+$CD$2)*(1+每日報酬率!C105) -> 0.14502893 | D105: =D104*(1+$CD$2)*(1+每日報酬率!D105) -> 1.3152208 | E105: =E104*(1+$CD$2)*(1+每日報酬率!E105) -> 0.11295619 | F105: =SUM(B105:E105) -> 1.5732059 | K105: =IFERROR(G106/每日收盤價!B105,0) -> 0 | L105: =IFERROR(H106/每日收盤價!C105,0) -> 0 | M105: =IFERROR(I106/每日收盤價!D105,0) -> 0.0038501537 | N105: =IFERROR(J106/每日收盤價!E105,0) -> 0 | O105: =SUM(K105:N105) -> 0.0038501537
A106: 2024-06-13 | B106: =B105*(1+$CD$2)*(1+每日報酬率!B106) -> 0 | C106: =C105*(1+$CD$2)*(1+每日報酬率!C106) -> 0.14850963 | D106: =D105*(1+$CD$2)*(1+每日報酬率!D106) -> 1.3296897 | E106: =E105*(1+$CD$2)*(1+每日報酬率!E106) -> 0.12034179 | F106: =SUM(B106:E106) -> 1.5985411 | I106: 3.4997897 | K106: =IFERROR(G107/每日收盤價!B106,0) -> 0 | L106: =IFERROR(H107/每日收盤價!C106,0) -> 0 | M106: =IFERROR(I107/每日收盤價!D106,0) -> 0 | N106: =IFERROR(J107/每日收盤價!E106,0) -> 0 | O106: =SUM(K106:N106) -> 0
A107: 2024-06-14 | B107: =B106*(1+$CD$2)*(1+每日報酬率!B107) -> 0 | C107: =C106*(1+$CD$2)*(1+每日報酬率!C107) -> 0.15315055 | D107: =D106*(1+$CD$2)*(1+每日報酬率!D107) -> 1.3340303 | E107: =E106*(1+$CD$2)*(1+每日報酬率!E107) -> 0.12121068 | F107: =SUM(B107:E107) -> 1.6083916 | K107: =IFERROR(G108/每日收盤價!B107,0) -> 0 | L107: =IFERROR(H108/每日收盤價!C107,0) -> 0 | M107: =IFERROR(I108/每日收盤價!D107,0) -> 0 | N107: =IFERROR(J108/每日收盤價!E107,0) -> 0 | O107: =SUM(K107:N107) -> 0
A108: 2024-06-17 | B108: =B107*(1+$CD$2)*(1+每日報酬率!B108) -> 0 | C108: =C107*(1+$CD$2)*(1+每日報酬率!C108) -> 0.15469753 | D108: =D107*(1+$CD$2)*(1+每日報酬率!D108) -> 1.3325834 | E108: =E107*(1+$CD$2)*(1+每日報酬率!E108) -> 0.11990734 | F108: =SUM(B108:E108) -> 1.6071883 | K108: =IFERROR(G109/每日收盤價!B108,0) -> 0 | L108: =IFERROR(H109/每日收盤價!C108,0) -> 0 | M108: =IFERROR(I109/每日收盤價!D108,0) -> 0 | N108: =IFERROR(J109/每日收盤價!E108,0) -> 0 | O108: =SUM(K108:N108) -> 0
A109: 2024-06-18 | B109: =B108*(1+$CD$2)*(1+每日報酬率!B109) -> 0 | C109: =C108*(1+$CD$2)*(1+每日報酬率!C109) -> 0.1535373 | D109: =D108*(1+$CD$2)*(1+每日報酬率!D109) -> 1.364415 | E109: =E108*(1+$CD$2)*(1+每日報酬率!E109) -> 0.12207958 | F109: =SUM(B109:E109) -> 1.6400318 | G109: 6.43 | K109: =IFERROR(G110/每日收盤價!B109,0) -> 0 | L109: =IFERROR(H110/每日收盤價!C109,0) -> 0 | M109: =IFERROR(I110/每日收盤價!D109,0) -> 0 | N109: =IFERROR(J110/每日收盤價!E109,0) -> 0 | O109: =SUM(K109:N109) -> 0
A110: 2024-06-19 | B110: =B109*(1+$CD$2)*(1+每日報酬率!B110) -> 0 | C110: =C109*(1+$CD$2)*(1+每日報酬率!C110) -> 0.15701799 | D110: =D109*(1+$CD$2)*(1+每日報酬率!D110) -> 1.4193967 | E110: =E109*(1+$CD$2)*(1+每日報酬率!E110) -> 0.12903073 | F110: =SUM(B110:E110) -> 1.7054454 | K110: =IFERROR(G111/每日收盤價!B110,0) -> 0 | L110: =IFERROR(H111/每日收盤價!C110,0) -> 0 | M110: =IFERROR(I111/每日收盤價!D110,0) -> 0 | N110: =IFERROR(J111/每日收盤價!E110,0) -> 0 | O110: =SUM(K110:N110) -> 0
A111: 2024-06-20 | B111: =B110*(1+$CD$2)*(1+每日報酬率!B111) -> 0 | C111: =C110*(1+$CD$2)*(1+每日報酬率!C111) -> 0.16823356 | D111: =D110*(1+$CD$2)*(1+每日報酬率!D111) -> 1.4193967 | E111: =E110*(1+$CD$2)*(1+每日報酬率!E111) -> 0.13033407 | F111: =SUM(B111:E111) -> 1.7179643 | K111: =IFERROR(G112/每日收盤價!B111,0) -> 0 | L111: =IFERROR(H112/每日收盤價!C111,0) -> 0 | M111: =IFERROR(I112/每日收盤價!D111,0) -> 0 | N111: =IFERROR(J112/每日收盤價!E111,0) -> 0 | O111: =SUM(K111:N111) -> 0
A112: 2024-06-21 | B112: =B111*(1+$CD$2)*(1+每日報酬率!B112) -> 0 | C112: =C111*(1+$CD$2)*(1+每日報酬率!C112) -> 0.16397938 | D112: =D111*(1+$CD$2)*(1+每日報酬率!D112) -> 1.4034809 | E112: =E111*(1+$CD$2)*(1+每日報酬率!E112) -> 0.12946517 | F112: =SUM(B112:E112) -> 1.6969255 | K112: =IFERROR(G113/每日收盤價!B112,0) -> 0 | L112: =IFERROR(H113/每日收盤價!C112,0) -> 0 | M112: =IFERROR(I113/每日收盤價!D112,0) -> 0 | N112: =IFERROR(J113/每日收盤價!E112,0) -> 0 | O112: =SUM(K112:N112) -> 0
A113: 2024-06-24 | B113: =B112*(1+$CD$2)*(1+每日報酬率!B113) -> 0 | C113: =C112*(1+$CD$2)*(1+每日報酬率!C113) -> 0.15933845 | D113: =D112*(1+$CD$2)*(1+每日報酬率!D113) -> 1.3600743 | E113: =E112*(1+$CD$2)*(1+每日報酬率!E113) -> 0.12251402 | F113: =SUM(B113:E113) -> 1.6419268 | K113: =IFERROR(G114/每日收盤價!B113,0) -> 0 | L113: =IFERROR(H114/每日收盤價!C113,0) -> 0 | M113: =IFERROR(I114/每日收盤價!D113,0) -> 0 | N113: =IFERROR(J114/每日收盤價!E113,0) -> 0 | O113: =SUM(K113:N113) -> 0
A114: 2024-06-25 | B114: =B113*(1+$CD$2)*(1+每日報酬率!B114) -> 0 | C114: =C113*(1+$CD$2)*(1+每日報酬率!C114) -> 0.16320589 | D114: =D113*(1+$CD$2)*(1+每日報酬率!D114) -> 1.3673087 | E114: =E113*(1+$CD$2)*(1+每日報酬率!E114) -> 0.12034179 | F114: =SUM(B114:E114) -> 1.6508564 | K114: =IFERROR(G115/每日收盤價!B114,0) -> 0 | L114: =IFERROR(H115/每日收盤價!C114,0) -> 0 | M114: =IFERROR(I115/每日收盤價!D114,0) -> 0 | N114: =IFERROR(J115/每日收盤價!E114,0) -> 0 | O114: =SUM(K114:N114) -> 0
A115: 2024-06-26 | B115: =B114*(1+$CD$2)*(1+每日報酬率!B115) -> 0 | C115: =C114*(1+$CD$2)*(1+每日報酬率!C115) -> 0.16243241 | D115: =D114*(1+$CD$2)*(1+每日報酬率!D115) -> 1.3890121 | E115: =E114*(1+$CD$2)*(1+每日報酬率!E115) -> 0.12207958 | F115: =SUM(B115:E115) -> 1.673524 | K115: =IFERROR(G116/每日收盤價!B115,0) -> 0 | L115: =IFERROR(H116/每日收盤價!C115,0) -> 0 | M115: =IFERROR(I116/每日收盤價!D115,0) -> 0 | N115: =IFERROR(J116/每日收盤價!E115,0) -> 0 | O115: =SUM(K115:N115) -> 0
...

Sheet 標準化權重
A1: date | B1: 2308 | C1: 2317 | D1: 2330 | E1: 2454
A2: 2024-01-03
A3: 2024-01-04 | B3: =投資後權重!B3/投資後權重!$F3 -> 0 | C3: =投資後權重!C3/投資後權重!$F3 -> 0.080420933 | D3: =投資後權重!D3/投資後權重!$F3 -> 0.83896756 | E3: =投資後權重!E3/投資後權重!$F3 -> 0.08061151 | F3: =SUM(B3:E3) -> 1
A4: 2024-01-05 | B4: =投資後權重!B4/投資後權重!$F4 -> 0 | C4: =投資後權重!C4/投資後權重!$F4 -> 0.080938457 | D4: =投資後權重!D4/投資後權重!$F4 -> 0.83854326 | E4: =投資後權重!E4/投資後權重!$F4 -> 0.080518287 | F4: =SUM(B4:E4) -> 1
A5: 2024-01-08 | B5: =投資後權重!B5/投資後權重!$F5 -> 0 | C5: =投資後權重!C5/投資後權重!$F5 -> 0.078353646 | D5: =投資後權重!D5/投資後權重!$F5 -> 0.8418663 | E5: =投資後權重!E5/投資後權重!$F5 -> 0.079780051 | F5: =SUM(B5:E5) -> 1
A6: 2024-01-09 | B6: =投資後權重!B6/投資後權重!$F6 -> 0 | C6: =投資後權重!C6/投資後權重!$F6 -> 0.077607581 | D6: =投資後權重!D6/投資後權重!$F6 -> 0.84229029 | E6: =投資後權重!E6/投資後權重!$F6 -> 0.08010213 | F6: =SUM(B6:E6) -> 1
A7: 2024-01-10 | B7: =投資後權重!B7/投資後權重!$F7 -> 0 | C7: =投資後權重!C7/投資後權重!$F7 -> 0.07714688 | D7: =投資後權重!D7/投資後權重!$F7 -> 0.84277688 | E7: =投資後權重!E7/投資後權重!$F7 -> 0.080076236 | F7: =SUM(B7:E7) -> 1
A8: 2024-01-11 | B8: =投資後權重!B8/投資後權重!$F8 -> 0 | C8: =投資後權重!C8/投資後權重!$F8 -> 0.077306469 | D8: =投資後權重!D8/投資後權重!$F8 -> 0.8431965 | E8: =投資後權重!E8/投資後權重!$F8 -> 0.079497032 | F8: =SUM(B8:E8) -> 1
A9: 2024-01-12 | B9: =投資後權重!B9/投資後權重!$F9 -> 0 | C9: =投資後權重!C9/投資後權重!$F9 -> 0.077489293 | D9: =投資後權重!D9/投資後權重!$F9 -> 0.84230599 | E9: =投資後權重!E9/投資後權重!$F9 -> 0.080204722 | F9: =SUM(B9:E9) -> 1
A10: 2024-01-15 | B10: =投資後權重!B10/投資後權重!$F10 -> 0 | C10: =投資後權重!C10/投資後權重!$F10 -> 0.076938154 | D10: =投資後權重!D10/投資後權重!$F10 -> 0.84337512 | E10: =投資後權重!E10/投資後權重!$F10 -> 0.079686729 | F10: =SUM(B10:E10) -> 1
A11: 2024-01-16 | B11: =投資後權重!B11/投資後權重!$F11 -> 0 | C11: =投資後權重!C11/投資後權重!$F11 -> 0.077791433 | D11: =投資後權重!D11/投資後權重!$F11 -> 0.84399752 | E11: =投資後權重!E11/投資後權重!$F11 -> 0.078211051 | F11: =SUM(B11:E11) -> 1
A12: 2024-01-17 | B12: =投資後權重!B12/投資後權重!$F12 -> 0 | C12: =投資後權重!C12/投資後權重!$F12 -> 0.076781599 | D12: =投資後權重!D12/投資後權重!$F12 -> 0.84632618 | E12: =投資後權重!E12/投資後權重!$F12 -> 0.076892225 | F12: =SUM(B12:E12) -> 1
A13: 2024-01-18 | B13: =投資後權重!B13/投資後權重!$F13 -> 0 | C13: =投資後權重!C13/投資後權重!$F13 -> 0.076811997 | D13: =投資後權重!D13/投資後權重!$F13 -> 0.84571162 | E13: =投資後權重!E13/投資後權重!$F13 -> 0.077476381 | F13: =SUM(B13:E13) -> 1
A14: 2024-01-19 | B14: =投資後權重!B14/投資後權重!$F14 -> 0 | C14: =投資後權重!C14/投資後權重!$F14 -> 0.073099168 | D14: =投資後權重!D14/投資後權重!$F14 -> 0.85173032 | E14: =投資後權重!E14/投資後權重!$F14 -> 0.075170512 | F14: =SUM(B14:E14) -> 1
... A479: 2025-12-22 | B479: =投資後權重!B479/投資後權重!$F479 -> 0 | C479: =投資後權重!C479/投資後權重!$F479 -> 0.07194995 | D479: =投資後權重!D479/投資後權重!$F479 -> 0.88024083 | E479: =投資後權重!E479/投資後權重!$F479 -> 0.047809221 | F479: =SUM(B479:E479) -> 1

Sheet 驗證 
A1: date | B1: 2308 | C1: 2317 | D1: 2330 | E1: 2454
A2: 2024-01-03
A3: 2024-01-04 | B3: =標準化權重!B3-每日權重!B3 -> 0 | C3: =標準化權重!C3-每日權重!C3 -> 0 | D3: =標準化權重!D3-每日權重!D3 -> 0 | E3: =標準化權重!E3-每日權重!E3 -> 0
A4: 2024-01-05 | B4: =標準化權重!B4-每日權重!B4 -> 0 | C4: =標準化權重!C4-每日權重!C4 -> 0 | D4: =標準化權重!D4-每日權重!D4 -> 0 | E4: =標準化權重!E4-每日權重!E4 -> 0
A5: 2024-01-08 | B5: =標準化權重!B5-每日權重!B5 -> 0 | C5: =標準化權重!C5-每日權重!C5 -> 0 | D5: =標準化權重!D5-每日權重!D5 -> 0 | E5: =標準化權重!E5-每日權重!E5 -> 0
A6: 2024-01-09 | B6: =標準化權重!B6-每日權重!B6 -> 0 | C6: =標準化權重!C6-每日權重!C6 -> 0 | D6: =標準化權重!D6-每日權重!D6 -> 0 | E6: =標準化權重!E6-每日權重!E6 -> 0
A7: 2024-01-10 | B7: =標準化權重!B7-每日權重!B7 -> 0 | C7: =標準化權重!C7-每日權重!C7 -> 0 | D7: =標準化權重!D7-每日權重!D7 -> 0 | E7: =標準化權重!E7-每日權重!E7 -> 0
A8: 2024-01-11 | B8: =標準化權重!B8-每日權重!B8 -> 0 | C8: =標準化權重!C8-每日權重!C8 -> 0 | D8: =標準化權重!D8-每日權重!D8 -> 0 | E8: =標準化權重!E8-每日權重!E8 -> 0
A9: 2024-01-12 | B9: =標準化權重!B9-每日權重!B9 -> 0 | C9: =標準化權重!C9-每日權重!C9 -> 0 | D9: =標準化權重!D9-每日權重!D9 -> 0 | E9: =標準化權重!E9-每日權重!E9 -> 0
A10: 2024-01-15 | B10: =標準化權重!B10-每日權重!B10 -> 0 | C10: =標準化權重!C10-每日權重!C10 -> 0 | D10: =標準化權重!D10-每日權重!D10 -> 0 | E10: =標準化權重!E10-每日權重!E10 -> 0
A11: 2024-01-16 | B11: =標準化權重!B11-每日權重!B11 -> 0 | C11: =標準化權重!C11-每日權重!C11 -> 0 | D11: =標準化權重!D11-每日權重!D11 -> 0 | E11: =標準化權重!E11-每日權重!E11 -> 0
A12: 2024-01-17 | B12: =標準化權重!B12-每日權重!B12 -> 0 | C12: =標準化權重!C12-每日權重!C12 -> 0 | D12: =標準化權重!D12-每日權重!D12 -> 0 | E12: =標準化權重!E12-每日權重!E12 -> 0
A13: 2024-01-18 | B13: =標準化權重!B13-每日權重!B13 -> 0 | C13: =標準化權重!C13-每日權重!C13 -> 0 | D13: =標準化權重!D13-每日權重!D13 -> 0 | E13: =標準化權重!E13-每日權重!E13 -> 0
A14: 2024-01-19 | B14: =標準化權重!B14-每日權重!B14 -> 0 | C14: =標準化權重!C14-每日權重!C14 -> 0 | D14: =標準化權重!D14-每日權重!D14 -> 0 | E14: =標準化權重!E14-每日權重!E14 -> 0
... A479: 2025-12-22 | B479: =標準化權重!B479-每日權重!B479 -> -0.05720561 | C479: =標準化權重!C479-每日權重!C479 -> 0.0013164257 | D479: =標準化權重!D479-每日權重!D479 -> 0.0080799633 | E479: =標準化權重!E479-每日權重!E479 -> 0.047809221

Sheet 每日權重
A1: date | B1: 2308 | C1: 2317 | D1: 2330 | E1: 2454
A2: 2024-01-03 | C2: 0.080652758 | D2: 0.83447278 | E2: 0.084874462
A3: 2024-01-04 | C3: 0.080420933 | D3: 0.83896756 | E3: 0.08061151
A4: 2024-01-05 | C4: 0.080938457 | D4: 0.83854326 | E4: 0.080518287
A5: 2024-01-08 | C5: 0.078353646 | D5: 0.8418663 | E5: 0.079780051
A6: 2024-01-09 | C6: 0.077607581 | D6: 0.84229029 | E6: 0.08010213
A7: 2024-01-10 | C7: 0.07714688 | D7: 0.84277688 | E7: 0.080076236
A8: 2024-01-11 | C8: 0.077306469 | D8: 0.8431965 | E8: 0.079497032
A9: 2024-01-12 | C9: 0.077489293 | D9: 0.84230599 | E9: 0.080204722
A10: 2024-01-15 | C10: 0.076938154 | D10: 0.84337512 | E10: 0.079686729
A11: 2024-01-16 | C11: 0.077791433 | D11: 0.84399752 | E11: 0.078211051
A12: 2024-01-17 | C12: 0.076781599 | D12: 0.84632618 | E12: 0.076892225
A13: 2024-01-18 | C13: 0.076811997 | D13: 0.84571162 | E13: 0.077476381
... A427: 2025-10-07 | C427: 0.072445691 | D427: 0.88039854 | E427: 0.047155769
A428: 2025-10-08 | B428: 0.060389793 | C428: 0.072760251 | D428: 0.86684996
A429: 2025-10-09 | B429: 0.060571624 | C429: 0.070549607 | D429: 0.86887877
A430: 2025-10-13 | B430: 0.063461043 | C430: 0.068939277 | D430: 0.86759968
A431: 2025-10-14 | B431: 0.061026723 | C431: 0.066572174 | D431: 0.8724011
A432: 2025-10-15 | B432: 0.060855462 | C432: 0.065038529 | D432: 0.87410601
A433: 2025-10-16 | B433: 0.060384435 | C433: 0.069011766 | D433: 0.8706038
A434: 2025-10-17 | B434: 0.060113176 | C434: 0.071596127 | D434: 0.8682907
A435: 2025-10-20 | B435: 0.059719097 | C435: 0.073714464 | D435: 0.86656644
A436: 2025-10-21 | B436: 0.059986363 | C436: 0.07383587 | D436: 0.86617777
A437: 2025-10-22 | B437: 0.06063049 | C437: 0.075721601 | D437: 0.86364791
A438: 2025-10-23 | B438: 0.060496007 | C438: 0.075200439 | D438: 0.86430355
A439: 2025-10-27 | B439: 0.062597761 | C439: 0.075754612 | D439: 0.86164763
... A479: 2025-12-22 | B479: 0.05720561 | C479: 0.070633525 | D479: 0.87216086

Sheet 現金股利
A1: date | B1: 2308 | C1: 2317 | D1: 2330 | E1: 2454
A2: 45294
A3: 45295 | E3: 24.6
A4: 45299
A5: 45302
A6: 45306
A7: 45307
A8: 45308
A9: 45309
A10: 45310
A11: 45313
A12: 45316
A13: 45344
A14: 45348
A15: 45349
... A22: 45365
A23: 45369 | D23: 3.4997897
A24: 45370
A25: 45371
A26: 45372
A27: 45373
A28: 45376
A29: 45377
A30: 45378
A31: 45379
A32: 45380
A33: 45383
A34: 45384
A35: 45385
... A67: 45455
A68: 45456 | D68: 3.4997897
A69: 45457
A70: 45460
A71: 45461 | B71: 6.43
A72: 45462
A73: 45463
A74: 45464
A75: 45467
A76: 45468
A77: 45469
...

Sheet 每日收盤價
A1: date | B1: 2308 | C1: 2317 | D1: 2330 | E1: 2454
A2: 2024-01-03 | C2: 104.5 | D2: 578 | E2: 953
A3: 2024-01-04 | C3: 104 | D3: 580 | E3: 928
A4: 2024-01-05 | C4: 104 | D4: 576 | E4: 921
A5: 2024-01-08 | C5: 101.5 | D5: 583 | E5: 920
A6: 2024-01-09 | C6: 101 | D6: 586 | E6: 928
A7: 2024-01-10 | C7: 100 | D7: 584 | E7: 924
A8: 2024-01-11 | C8: 100.5 | D8: 586 | E8: 920
A9: 2024-01-12 | C9: 100.5 | D9: 584 | E9: 926
A10: 2024-01-15 | C10: 100 | D10: 586 | E10: 922
A11: 2024-01-16 | C11: 100 | D11: 580 | E11: 895
A12: 2024-01-17 | C12: 98.6 | D12: 581 | E12: 879
A13: 2024-01-18 | C13: 99.9 | D13: 588 | E13: 897
... A427: 2025-10-07 | C427: 228.5 | D427: 1435 | E427: 1325
A428: 2025-10-08 | B428: 981 | C428: 225 | D428: 1415
A429: 2025-10-09 | B429: 999 | C429: 221.5 | D429: 1440
A430: 2025-10-13 | B430: 1030 | C430: 213 | D430: 1415
A431: 2025-10-14 | B431: 992 | C431: 206 | D431: 1425
A432: 2025-10-15 | B432: 1015 | C432: 206.5 | D432: 1465
A433: 2025-10-16 | B433: 1025 | C433: 223 | D433: 1485
A434: 2025-10-17 | B434: 999 | C434: 226.5 | D434: 1450
A435: 2025-10-20 | B435: 1015 | C435: 238.5 | D435: 1480
A436: 2025-10-21 | B436: 1020 | C436: 239 | D436: 1480
A437: 2025-10-22 | B437: 1020 | C437: 242.5 | D437: 1460
A438: 2025-10-23 | B438: 1010 | C438: 239 | D438: 1450
A439: 2025-10-27 | B439: 1070 | C439: 246.5 | D439: 1480
... A479: 2025-12-22 | B479: 953 | C479: 224 | D479: 1465

Sheet 每日報酬率
A1: date | B1: 2308 | C1: 2317 | D1: 2330 | E1: 2454
A2: 2024-01-03 | C2: 0 | D2: 0 | E2: 0
A3: 2024-01-04 | C3: -0.004784689 | D3: 0.0034602076 | E3: -0.026232949
A4: 2024-01-05 | C4: 0 | D4: -0.0068965517 | E4: -0.0075431034
A5: 2024-01-08 | C5: -0.024038462 | D5: 0.012152778 | E5: -0.0010857763
A6: 2024-01-09 | C6: -0.0049261084 | D6: 0.0051457976 | E6: 0.0086956522
A7: 2024-01-10 | C7: -0.0099009901 | D7: -0.0034129693 | E7: -0.0043103448
A8: 2024-01-11 | C8: 0.005 | D8: 0.0034246575 | E8: -0.0043290043
A9: 2024-01-12 | C9: 0 | D9: -0.0034129693 | E9: 0.0065217391
A10: 2024-01-15 | C10: -0.0049751244 | D10: 0.0034246575 | E10: -0.0043196544
A11: 2024-01-16 | C11: 0 | D11: -0.010238908 | E11: -0.029284165
A12: 2024-01-17 | C12: -0.014 | D12: 0.0017241379 | E12: -0.017877095
A13: 2024-01-18 | C13: 0.013184584 | D13: 0.012048193 | E13: 0.020477816
... A427: 2025-10-07 | C427: 0.0088300221 | D427: 0.025 | E427: 0.0037878788
A428: 2025-10-08 | B428: -0.0060790274 | C428: -0.015317287 | D428: -0.013937282
A429: 2025-10-09 | B429: 0.018348624 | C429: -0.015555556 | D429: 0.017667845
A430: 2025-10-13 | B430: 0.031031031 | C430: -0.038374718 | D430: -0.017361111
A431: 2025-10-14 | B431: -0.036893204 | C431: -0.03286385 | D431: 0.0070671378
A432: 2025-10-15 | B432: 0.023185484 | C432: 0.0024271845 | D432: 0.028070175
A433: 2025-10-16 | B433: 0.0098522167 | C433: 0.079903148 | D433: 0.013651877
A434: 2025-10-17 | B434: -0.025365854 | C434: 0.015695067 | D434: -0.023569024
A435: 2025-10-20 | B435: 0.016016016 | C435: 0.052980132 | D435: 0.020689655
A436: 2025-10-21 | B436: 0.0049261084 | C436: 0.0020964361 | D436: 0
A437: 2025-10-22 | B437: 0 | C437: 0.014644351 | D437: -0.013513514
A438: 2025-10-23 | B438: -0.0098039216 | C438: -0.01443299 | D438: -0.0068493151
A439: 2025-10-27 | B439: 0.059405941 | C439: 0.031380753 | D439: 0.020689655
... A479: 2025-12-22 | B479: 0.046103183 | C479: 0.011286682 | D479: 0.024475524

Sheet 每日貢獻度
A1: date | B1: 2308 | C1: 2317 | D1: 2330 | E1: 2454 | F1: total
A2: 2024-01-03 | C2: 0 | D2: 0 | E2: 0 | F2: 0
A3: 2024-01-04 | C3: -0.00038589836 | D3: 0.0028874491 | E3: -0.0022265074 | F3: 0.00027504329
A4: 2024-01-05 | C4: 0 | D4: -0.0057859831 | E4: -0.00060806096 | F4: -0.0063940441
A5: 2024-01-08 | C5: -0.001945636 | D5: 0.01019063 | E5: -8.742485e-05 | F5: 0.008157569
A6: 2024-01-09 | C6: -0.00038597855 | D6: 0.0043320736 | E6: 0.00069373957 | F6: 0.0046398346
A7: 2024-01-10 | C7: -0.00076839189 | D7: -0.0028747109 | E7: -0.0003452678 | F7: -0.0039883706
A8: 2024-01-11 | C8: 0.0003857344 | D8: 0.0028862222 | E8: -0.00034665037 | F8: 0.0029253062
A9: 2024-01-12 | C9: 0 | D9: -0.0028778038 | E9: 0.0005184589 | F9: -0.0023593448
A10: 2024-01-15 | C10: -0.00038551887 | D10: 0.0028846095 | E10: -0.00034645668 | F10: 0.002152634
A11: 2024-01-16 | C11: 0 | D11: -0.0086352401 | E11: -0.0023335593 | F11: -0.010968799
A12: 2024-01-17 | C12: -0.0010890801 | D12: 0.0014551681 | E12: -0.0013981864 | F12: -0.0010320983
A13: 2024-01-18 | C13: 0.0010123335 | D13: 0.010196701 | E13: 0.0015745848 | F13: 0.012783619
... A427: 2025-10-07 | C427: 0.00064855102 | D427: 0.021962575 | E427: 0.00018200225 | F427: 0.022793128
A428: 2025-10-08 | B428: -0.00036434551 | C428: -0.0011164708 | D428: -0.012086071 | F428: -0.013566887
A429: 2025-10-09 | B429: 0.0011080696 | C429: -0.0011318261 | D429: 0.01531537 | F429: 0.015291614
A430: 2025-10-13 | B430: 0.0018796 | C430: -0.0027073213 | D430: -0.015084701 | F430: -0.015912422
A431: 2025-10-14 | B431: -0.0023412812 | C431: -0.00226561 | D431: 0.0061314465 | F431: 0.0015245553
A432: 2025-10-15 | B432: 0.0014149341 | C432: 0.00016158295 | D432: 0.024488452 | F432: 0.026064969
A433: 2025-10-16 | B433: 0.0005995612 | C433: 0.0051967832 | D433: 0.011933188 | F433: 0.017729532
A434: 2025-10-17 | B434: -0.0015317027 | C434: 0.0010831443 | D434: -0.020519281 | F434: -0.02096784
A435: 2025-10-20 | B435: 0.00096277359 | C435: 0.0037931723 | D435: 0.017964635 | F435: 0.022720581
A436: 2025-10-21 | B436: 0.00029418274 | C436: 0.00015453766 | D436: 0 | F436: 0.0004487204
A437: 2025-10-22 | B437: 0 | C437: 0.0010812784 | D437: -0.011705105 | F437: -0.010623827
A438: 2025-10-23 | B438: -0.00059441657 | C438: -0.0010928891 | D438: -0.0059153966 | F438: -0.0076027023
A439: 2025-10-27 | B439: 0.0035938222 | C439: 0.0023598464 | D439: 0.017882143 | F439: 0.023835811
... A479: 2025-12-22 | B479: 0.0025835103 | C479: 0.00080782641 | D479: 0.021352179 | F479: 0.024743515

Sheet 調倉摘要
A1: review_date | B1: effective_date | C1: total_stocks | D1: stocks_added | E1: stocks_removed | F1: stocks_maintained | G1: turnover
A2: 2024-01-03 | B2: 2024-01-03 | C2: 3 | D2: 0 | E2: 0 | F2: 3 | G2: 0
A3: 2024-03-29 | B3: 2024-04-09 | C3: 3 | D3: 0 | E3: 0 | F3: 3 | G3: 0.004579639
A4: 2024-06-28 | B4: 2024-07-05 | C4: 3 | D4: 0 | E4: 0 | F4: 3 | G4: 0.0011102038
A5: 2024-09-30 | B5: 2024-10-09 | C5: 3 | D5: 0 | E5: 0 | F5: 3 | G5: 0.0035705927
A6: 2024-12-31 | B6: 2025-01-08 | C6: 3 | D6: 0 | E6: 0 | F6: 3 | G6: 0.0039519779
A7: 2025-03-31 | B7: 2025-04-09 | C7: 3 | D7: 0 | E7: 0 | F7: 3 | G7: 0.0031541676
A8: 2025-06-30 | B8: 2025-07-07 | C8: 3 | D8: 0 | E8: 0 | F8: 3 | G8: 0.0022112385
A9: 2025-09-30 | B9: 2025-10-08 | C9: 3 | D9: 1 | E9: 1 | F9: 2 | G9: 0.057798385

Sheet 過渡期權重
A1: date | B1: portfolio_type | C1: stock_id | D1: weight
A2: 2024-03-29 | B2: old | C2: 2330 | D2: 0.83615071
A3: 2024-03-29 | B3: old | C3: 2454 | D3: 0.077382176
A4: 2024-03-29 | B4: old | C4: 2317 | D4: 0.086467117
A5: 2024-03-29 | B5: new | C5: 2330 | D5: 0.83736079
A6: 2024-03-29 | B6: new | C6: 2317 | D6: 0.082070491
A7: 2024-03-29 | B7: new | C7: 2454 | D7: 0.080568717
A8: 2024-04-01 | B8: old | C8: 2330 | D8: 0.83622279
A9: 2024-04-01 | B9: old | C9: 2454 | D9: 0.07600028
A10: 2024-04-01 | B10: old | C10: 2317 | D10: 0.087776931
A11: 2024-04-01 | B11: new | C11: 2330 | D11: 0.83753633
A12: 2024-04-01 | B12: new | C12: 2317 | D12: 0.083323987
A13: 2024-04-01 | B13: new | C13: 2454 | D13: 0.079139682
... A211: 2025-10-07 | B211: new | C211: 2308 | D211: 0.059934837
